Workbook
Name tier: Dex!$B$3:$B$1177
Name cost: #REF!
Name mons: Dex!$B$3:$B$1177

Sheet Main
B2: Check the different tabs at the bottom to navigate through encounter tables, or click/tap the links in the boxes on the right to access these tabs. | D2: Grass & Caves | E2: Fishing & Surfing | F2: Safari Zone | G2: Fossils
D3: Statics & Special Pokémon | E3: Raid Dens | F3: Egg Vendor & Game Corner | G3: Trades
D4: Gifts | E4: Mystery Gifts | F4: Unobtainables

Sheet Grass & Caves
C3: =Source!$C5 | D3: ROUTE 1 | H3: =Source!$C5 | I3: VIRIDIAN CITY | M3: =Source!$C5 | N3: ROUTE 22 | R3: =Source!$C5 | S3: ROUTE 21A | W3: =Source!$C5 | X3: ROUTE 2 | AB3: =Source!$C5 | AC3: VIRIDIAN FOREST | AG3: =Source!$C5 | AH3: FOREST EXPANSION | AL3: =Source!$C5 | AM3: DIGLETT CAVE | AQ3: =Source!$C5 | AR3: PEWTER CITY | AV3: =Source!$C5 | AW3: ROUTE 3 | BA3: =Source!$C5 | BB3: MT MOON 1F | BF3: =Source!$C5 | BG3: MT MOON B1F | BK3: =Source!$C5 | BL3: MT MOON B2F | BP3: =Source!$C5 | BQ3: ROUTE 4 | BU3: =Source!$C5 | BV3: ROUTE 24 | BZ3: =Source!$C5 | CA3: ROUTE 25 | CE3: =Source!$C5 | CF3: ROUTE 5 | CJ3: =Source!$C5 | CK3: ROUTE 6 | CO3: =Source!$C5 | CP3: ROUTE 11 | CT3: =Source!$C5 | CU3: DIGLETT CAVE B1F | CY3: =Source!$C5 | CZ3: ROUTE 9 | DD3: =Source!$C5 | DE3: ROUTE 10 | DI3: =Source!$C5 | DJ3: ROCK TUNNEL 1F | DN3: =Source!$C5 | DO3: ROCK TUNNEL B1F | DS3: =Source!$C5 | DT3: ROUTE 7 | DX3: =Source!$C5 | DY3: ROUTE 8 | EC3: =Source!$C5 | ED3: PKMN TOWER 3&5F | EH3: =Source!$C5 | EI3: PKMN TOWER 4F | EM3: =Source!$C5 | EN3: PKMN TOWER 6F | ER3: =Source!$C5 | ES3: PKMN TOWER 7F | EW3: =Source!$C5 | EX3: ROUTE 16 | FB3: =Source!$C5 | FC3: ROUTE 17 | FG3: =Source!$C5 | FH3: ROUTE 18 | FL3: =Source!$C5 | FM3: ROUTE 12 | FQ3: =Source!$C5 | FR3: ROUTE 13 | FV3: =Source!$C5 | FW3: ROUTE 14 | GA3: =Source!$C5 | GB3: ROUTE 15 | GF3: =Source!$C5 | GG3: ROUTE 23 | GK3: =Source!$C5 | GL3: SEAFOAM 1F | GP3: =Source!$C5 | GQ3: SEAFOAM B1F | GU3: =Source!$C5 | GV3: SEAFOAM B2F | GZ3: =Source!$C5 | HA3: SEAFOAM B3F | HE3: =Source!$C5 | HF3: SEAFOAM B4F | HJ3: =Source!$C5 | HK3: MANSION 1F | HO3: =Source!$C5 | HP3: MANSION 2F | HT3: =Source!$C5 | HU3: MANSION 3F | HY3: =Source!$C5 | HZ3: MANSION B1F | ID3: =Source!$C5 | IE3: POWER PLANT | II3: =Source!$C5 | IJ3: CERULEAN CAVE 1F | IN3: =Source!$C5 | IO3: CERULEAN CAVE 2F | IS3: =Source!$C5 | IT3: CERULEAN CAVE B1F | IX3: =Source!$C5 | IY3: MANSION 4F | JC3: =Source!$C5 | JD3: GOUGING'S ROOM | JH3: =Source!$C5 | JI3: VICTORY ROAD 1F | JM3: =Source!$C5 | JN3: VICTORY ROAD 2F | JR3: =Source!$C5 | JS3: VICTORY ROAD 3F | JW3: P O S T - G A M E | JY3: =Source!$C5 | JZ3: KINDLE ROAD | KD3: =Source!$C5 | KE3: MT. EMBER EXTERIOR | KI3: =Source!$C5 | KJ3: MT. EMBER 1F | KN3: =Source!$C5 | KO3: TREASURE BEACH | KS3: =Source!$C5 | KT3: ROCK TUNNEL (SECRET) | KX3: =Source!$C5 | KY3: CAPE BRINK | LC3: =Source!$C5 | LD3: BOND BRIDGE | LH3: =Source!$C5 | LI3: BERRY FOREST | LM3: =Source!$C5 | LN3: PKMN TOWER 8F | LR3: =Source!$C5 | LS3: PKMN TOWER 9F | LW3: =Source!$C5 | LX3: THREE ISLAND
C4: Rarity | D4: Pokémon | F4: Level | H4: Rarity | I4: Pokémon | K4: Level | M4: Rarity | N4: Pokémon | P4: Level | R4: Rarity | S4: Pokémon | U4: Level | W4: Rarity | X4: Pokémon | Z4: Level | AB4: Rarity | AC4: Pokémon | AE4: Level | AG4: Rarity | AH4: Pokémon | AJ4: Level | AL4: Rarity | AM4: Pokémon | AO4: Level | AQ4: Rarity | AR4: Pokémon | AT4: Level | AV4: Rarity | AW4: Pokémon | AY4: Level | BA4: Rarity | BB4: Pokémon | BD4: Level | BF4: Rarity | BG4: Pokémon | BI4: Level | BK4: Rarity | BL4: Pokémon | BN4: Level | BP4: Rarity | BQ4: Pokémon | BS4: Level | BU4: Rarity | BV4: Pokémon | BX4: Level | BZ4: Rarity | CA4: Pokémon | CC4: Level | CE4: Rarity | CF4: Pokémon | CH4: Level | CJ4: Rarity | CK4: Pokémon | CM4: Level | CO4: Rarity | CP4: Pokémon | CR4: Level | CT4: Rarity | CU4: Pokémon | CW4: Level | CY4: Rarity | CZ4: Pokémon | DB4: Level | DD4: Rarity | DE4: Pokémon | DG4: Level | DI4: Rarity | DJ4: Pokémon | DL4: Level | DN4: Rarity | DO4: Pokémon | DQ4: Level | DS4: Rarity | DT4: Pokémon | DV4: Level | DX4: Rarity | DY4: Pokémon | EA4: Level | EC4: Rarity | ED4: Pokémon | EF4: Level | EH4: Rarity | EI4: Pokémon | EK4: Level | EM4: Rarity | EN4: Pokémon | EP4: Level | ER4: Rarity | ES4: Pokémon | EU4: Level | EW4: Rarity | EX4: Pokémon | EZ4: Level | FB4: Rarity | FC4: Pokémon | FE4: Level | FG4: Rarity | FH4: Pokémon | FJ4: Level | FL4: Rarity | FM4: Pokémon | FO4: Level | FQ4: Rarity | FR4: Pokémon | FT4: Level | FV4: Rarity | FW4: Pokémon | FY4: Level | GA4: Rarity | GB4: Pokémon | GD4: Level | GF4: Rarity | GG4: Pokémon | GI4: Level | GK4: Rarity | GL4: Pokémon | GN4: Level | GP4: Rarity | GQ4: Pokémon | GS4: Level | GU4: Rarity | GV4: Pokémon | GX4: Level | GZ4: Rarity | HA4: Pokémon | HC4: Level | HE4: Rarity | HF4: Pokémon | HH4: Level | HJ4: Rarity | HK4: Pokémon | HM4: Level | HO4: Rarity | HP4: Pokémon | HR4: Level | HT4: Rarity | HU4: Pokémon | HW4: Level | HY4: Rarity | HZ4: Pokémon | IB4: Level | ID4: Rarity | IE4: Pokémon | IG4: Level | II4: Rarity | IJ4: Pokémon | IL4: Level | IN4: Rarity | IO4: Pokémon | IQ4: Level | IS4: Rarity | IT4: Pokémon | IV4: Level | IX4: Rarity | IY4: Pokémon | JA4: Level | JC4: Rarity | JD4: Pokémon | JF4: Level | JH4: Rarity | JI4: Pokémon | JK4: Level | JM4: Rarity | JN4: Pokémon | JP4: Level | JR4: Rarity | JS4: Pokémon | JU4: Level | JY4: Rarity | JZ4: Pokémon | KB4: Level | KD4: Rarity | KE4: Pokémon | KG4: Level | KI4: Rarity | KJ4: Pokémon | KL4: Level | KN4: Rarity | KO4: Pokémon | KQ4: Level | KS4: Rarity | KT4: Pokémon | KV4: Level | KX4: Rarity | KY4: Pokémon | LA4: Level | LC4: Rarity | LD4: Pokémon | LF4: Level | LH4: Rarity | LI4: Pokémon | LK4: Level | LM4: Rarity | LN4: Pokémon | LP4: Level | LR4: Rarity | LS4: Pokémon | LU4: Level | LW4: Rarity | LX4: Pokémon | LZ4: Level
C5: 0.2 | D5: {=IFERROR(VLOOKUP(E5:E16,Dex!$B$3:$N33,2,FALSE),"")} | E5: Bidoof | F5: 44231 | H5: 0.2 | I5: {=IFERROR(VLOOKUP(J5:J16,Dex!$B$3:$N33,2,FALSE),"")} | J5: Shinx | K5: 44625 | M5: 0.2 | N5: {=IFERROR(VLOOKUP(O5:O16,Dex!$B$3:$N33,2,FALSE),"")} | O5: Starly | P5: 44625 | R5: 0.2 | S5: {=IFERROR(VLOOKUP(T5:T16,Dex!$B$3:$N33,2,FALSE),"")} | T5: Wooper | U5: 45022 | W5: 0.2 | X5: {=IFERROR(VLOOKUP(Y5:Y16,Dex!$B$3:$N33,2,FALSE),"")} | Y5: Bidoof | Z5: 44625 | AB5: 0.2 | AC5: {=IFERROR(VLOOKUP(AD5:AD16,Dex!$B$3:$N33,2,FALSE),"")} | AD5: Caterpie | AE5: 44657 | AG5: 0.2 | AH5: {=IFERROR(VLOOKUP(AI5:AI16,Dex!$B$3:$N33,2,FALSE),"")} | AI5: Caterpie | AJ5: 44657 | AL5: 0.2 | AM5: {=IFERROR(VLOOKUP(AN5:AN16,Dex!$B$3:$N33,2,FALSE),"")} | AN5: Diglett | AO5: 44751 | AQ5: 0.2 | AR5: {=IFERROR(VLOOKUP(AS5:AS16,Dex!$B$3:$N33,2,FALSE),"")} | AS5: Grimer | AT5: 44751 | AV5: 0.2 | AW5: {=IFERROR(VLOOKUP(AX5:AX16,Dex!$B$3:$N33,2,FALSE),"")} | AX5: Fletchling | AY5: 44846 | BA5: 0.2 | BB5: {=IFERROR(VLOOKUP(BC5:BC16,Dex!$B$3:$N33,2,FALSE),"")} | BC5: Geodude | BD5: 44909 | BF5: 0.2 | BG5: {=IFERROR(VLOOKUP(BH5:BH16,Dex!$B$3:$N33,2,FALSE),"")} | BH5: Paras | BI5: 44909 | BK5: 0.2 | BL5: {=IFERROR(VLOOKUP(BM5:BM16,Dex!$B$3:$N33,2,FALSE),"")} | BM5: Varoom | BN5: 44909 | BP5: 0.2 | BQ5: {=IFERROR(VLOOKUP(BR5:BR16,Dex!$B$3:$N33,2,FALSE),"")} | BR5: Pidove | BS5: 13-15 | BU5: 0.2 | BV5: {=IFERROR(VLOOKUP(BW5:BW16,Dex!$B$3:$N33,2,FALSE),"")} | BW5: Snubbull | BX5: 14-16 | BZ5: 0.2 | CA5: {=IFERROR(VLOOKUP(CB5:CB16,Dex!$B$3:$N33,2,FALSE),"")} | CB5: Swablu | CC5: 16-18 | CE5: 0.2 | CF5: {=IFERROR(VLOOKUP(CG5:CG16,Dex!$B$3:$N33,2,FALSE),"")} | CG5: Meowth | CH5: 18-20 | CJ5: 0.2 | CK5: {=IFERROR(VLOOKUP(CL5:CL16,Dex!$B$3:$N33,2,FALSE),"")} | CL5: Sunkern | CM5: 16-18 | CO5: 0.2 | CP5: {=IFERROR(VLOOKUP(CQ5:CQ16,Dex!$B$3:$N33,2,FALSE),"")} | CQ5: Stufful | CR5: 23-25 | CT5: 0.2 | CU5: {=IFERROR(VLOOKUP(CV5:CV16,Dex!$B$3:$N33,2,FALSE),"")} | CV5: Diglett | CW5: 23-25 | CY5: 0.2 | CZ5: {=IFERROR(VLOOKUP(DA5:DA16,Dex!$B$3:$N33,2,FALSE),"")} | DA5: Shelmet | DB5: 25-27 | DD5: 0.2 | DE5: {=IFERROR(VLOOKUP(DF5:DF16,Dex!$B$3:$N33,2,FALSE),"")} | DF5: Voltorb | DG5: 27-29 | DI5: 0.2 | DJ5: {=IFERROR(VLOOKUP(DK5:DK16,Dex!$B$3:$N33,2,FALSE),"")} | DK5: Graveler | DL5: 29-31 | DN5: 0.2 | DO5: {=IFERROR(VLOOKUP(DP5:DP16,Dex!$B$3:$N33,2,FALSE),"")} | DP5: Sandslash | DQ5: 30-32 | DS5: 0.2 | DT5: {=IFERROR(VLOOKUP(DU5:DU16,Dex!$B$3:$N33,2,FALSE),"")} | DU5: Deerling | DV5: 36-38 | DX5: 0.2 | DY5: {=IFERROR(VLOOKUP(DZ5:DZ16,Dex!$B$3:$N33,2,FALSE),"")} | DZ5: Fomantis | EA5: 33-35 | EC5: 0.2 | ED5: {=IFERROR(VLOOKUP(EE5:EE16,Dex!$B$3:$N33,2,FALSE),"")} | EE5: Haunter | EF5: 45-47 | EH5: 0.2 | EI5: {=IFERROR(VLOOKUP(EJ5:EJ16,Dex!$B$3:$N33,2,FALSE),"")} | EJ5: Haunter | EK5: 45-47 | EM5: 0.2 | EN5: {=IFERROR(VLOOKUP(EO5:EO16,Dex!$B$3:$N33,2,FALSE),"")} | EO5: Haunter | EP5: 45-47 | ER5: 0.2 | ES5: {=IFERROR(VLOOKUP(ET5:ET16,Dex!$B$3:$N33,2,FALSE),"")} | ET5: Haunter | EU5: 45-47 | EW5: 0.2 | EX5: {=IFERROR(VLOOKUP(EY5:EY16,Dex!$B$3:$N33,2,FALSE),"")} | EY5: Heracross | EZ5: 36-38 | FB5: 0.2 | FC5: {=IFERROR(VLOOKUP(FD5:FD16,Dex!$B$3:$N33,2,FALSE),"")} | FD5: Weezing | FE5: 46-48 | FG5: 0.2 | FH5: {=IFERROR(VLOOKUP(FI5:FI16,Dex!$B$3:$N33,2,FALSE),"")} | FI5: Xatu | FJ5: 49-51 | FL5: 0.2 | FM5: {=IFERROR(VLOOKUP(FN5:FN16,Dex!$B$3:$N33,2,FALSE),"")} | FN5: Sneasel | FO5: 50-52 | FQ5: 0.2 | FR5: {=IFERROR(VLOOKUP(FS5:FS16,Dex!$B$3:$C33,2,FALSE),"")} | FS5: Tangrowth | FT5: 48-50 | FV5: 0.2 | FW5: {=IFERROR(VLOOKUP(FX5:FX16,Dex!$B$3:$N33,2,FALSE),"")} | FX5: Pelipper | FY5: 48-50 | GA5: 0.2 | GB5: {=IFERROR(VLOOKUP(GC5:GC16,Dex!$B$3:$N33,2,FALSE),"")} | GC5: Amoonguss | GD5: 49-51 | GF5: 0.2 | GG5: {=IFERROR(VLOOKUP(GH5:GH16,Dex!$B$3:$N33,2,FALSE),"")} | GH5: Primeape | GI5: 33-35 | GK5: 0.2 | GL5: {=IFERROR(VLOOKUP(GM5:GM16,Dex!$B$3:$N33,2,FALSE),"")} | GM5: Piloswine | GN5: 62-64 | GP5: 0.2 | GQ5: {=IFERROR(VLOOKUP(GR5:GR16,Dex!$B$3:$N33,2,FALSE),"")} | GR5: Piloswine | GS5: 62-64 | GU5: 0.2 | GV5: {=IFERROR(VLOOKUP(GW5:GW16,Dex!$B$3:$N33,2,FALSE),"")} | GW5: Abomasnow | GX5: 62-64 | GZ5: 0.2 | HA5: {=IFERROR(VLOOKUP(HB5:HB16,Dex!$B$3:$N33,2,FALSE),"")} | HB5: Piloswine | HC5: 62-64 | HE5: 0.2 | HF5: {=IFERROR(VLOOKUP(HG5:HG16,Dex!$B$3:$N33,2,FALSE),"")} | HG5: Piloswine | HH5: 62-64 | HJ5: 0.2 | HK5: {=IFERROR(VLOOKUP(HL5:HL16,Dex!$B$3:$N33,2,FALSE),"")} | HL5: Raticate | HM5: 63-65 | HO5: 0.2 | HP5: {=IFERROR(VLOOKUP(HQ5:HQ16,Dex!$B$3:$N33,2,FALSE),"")} | HQ5: Gumshoos | HR5: 63-65 | HT5: 0.2 | HU5: {=IFERROR(VLOOKUP(HV5:HV16,Dex!$B$3:$N33,2,FALSE),"")} | HV5: Bewear | HW5: 63-65 | HY5: 0.2 | HZ5: {=IFERROR(VLOOKUP(IA5:IA16,Dex!$B$3:$N33,2,FALSE),"")} | IA5: Raticate | IB5: 63-65 | ID5: 0.2 | IE5: {=IFERROR(VLOOKUP(IF5:IF16,Dex!$B$3:$N33,2,FALSE),"")} | IF5: Magneton | IG5: 63-65 | II5: 0.2 | IJ5: {=IFERROR(VLOOKUP(IK5:IK16,Dex!$B$3:$N33,2,FALSE),"")} | IK5: Parasect | IL5: 68-70 | IN5: 0.2 | IO5: {=IFERROR(VLOOKUP(IP5:IP16,Dex!$B$3:$N33,2,FALSE),"")} | IP5: Brute Bonnet | IQ5: 68-70 | IS5: 0.2 | IT5: {=IFERROR(VLOOKUP(IU5:IU16,Dex!$B$3:$N33,2,FALSE),"")} | IU5: Iron Treads | IV5: 68-70 | IX5: 0.2 | IY5: {=IFERROR(VLOOKUP(IZ5:IZ16,Dex!$B$3:$N33,2,FALSE),"")} | IZ5: Unown | JA5: 75-77 | JC5: 0.2 | JD5: {=IFERROR(VLOOKUP(JE5:JE16,Dex!$B$3:$N33,2,FALSE),"")} | JE5: Unown | JF5: 75-77 | JH5: 0.2 | JI5: {=IFERROR(VLOOKUP(JJ5:JJ16,Dex!$B$3:$N33,2,FALSE),"")} | JJ5: Iron Valiant | JK5: 80-82 | JM5: 0.2 | JN5: {=IFERROR(VLOOKUP(JO5:JO16,Dex!$B$3:$N33,2,FALSE),"")} | JO5: Baxcalibur | JP5: 80-82 | JR5: 0.2 | JS5: {=IFERROR(VLOOKUP(JT5:JT16,Dex!$B$3:$N33,2,FALSE),"")} | JT5: Dragonite | JU5: 80-82 | JY5: 0.2 | JZ5: {=IFERROR(VLOOKUP(KA5:KA16,Dex!$B$3:$N33,2,FALSE),"")} | KA5: Absol | KB5: 83-85 | KD5: 0.2 | KE5: {=IFERROR(VLOOKUP(KF5:KF16,Dex!$B$3:$N33,2,FALSE),"")} | KF5: Doduo-Sevii | KG5: 60-65 | KI5: 0.2 | KJ5: {=IFERROR(VLOOKUP(KK5:KK16,Dex!$B$3:$N33,2,FALSE),"")} | KK5: Torkoal | KL5: 85-85 | KN5: 0.2 | KO5: {=IFERROR(VLOOKUP(KP5:KP16,Dex!$B$3:$N33,2,FALSE),"")} | KP5: Sirfetch'd | KQ5: 85-85 | KS5: 0.2 | KT5: {=IFERROR(VLOOKUP(KU5:KU16,Dex!$B$3:$N33,2,FALSE),"")} | KU5: Ursaluna | KV5: 85-85 | KX5: 0.2 | KY5: {=IFERROR(VLOOKUP(KZ5:KZ16,Dex!$B$3:$N33,2,FALSE),"")} | KZ5: Electrode-Hisui | LA5: 85-85 | LC5: 0.2 | LD5: {=IFERROR(VLOOKUP(LE5:LE16,Dex!$B$3:$N33,2,FALSE),"")} | LE5: Decidueye-Hisui | LF5: 85-85 | LH5: 0.2 | LI5: {=IFERROR(VLOOKUP(LJ5:LJ16,Dex!$B$3:$N33,2,FALSE),"")} | LJ5: Carnivine-Sevii | LK5: 85-85 | LM5: 0.2 | LN5: {=IFERROR(VLOOKUP(LO5:LO16,Dex!$B$3:$N33,2,FALSE),"")} | LO5: Teddiursa-Sevii | LP5: 85-85 | LR5: 0.2 | LS5: {=IFERROR(VLOOKUP(LT5:LT16,Dex!$B$3:$N33,2,FALSE),"")} | LT5: Wishiwashi-Sevii | LU5: 85-85 | LW5: 0.2 | LX5: {=IFERROR(VLOOKUP(LY5:LY16,Dex!$B$3:$N33,2,FALSE),"")} | LY5: Dunsparce | LZ5: 85-85
C6: 0.2 | E6: Zigzagoon | F6: 44231 | H6: 0.2 | J6: Wooloo | K6: 44625 | M6: 0.2 | O6: Budew | P6: 44625 | R6: 0.2 | T6: Lechonk | U6: 45022 | W6: 0.2 | Y6: Sentret | Z6: 44625 | AB6: 0.2 | AD6: Weedle | AE6: 44657 | AG6: 0.2 | AI6: Weedle | AJ6: 44657 | AL6: 0.2 | AN6: Nacli | AO6: 44751 | AQ6: 0.2 | AS6: Starly | AT6: 44751 | AV6: 0.2 | AX6: Ekans | AY6: 44846 | BA6: 0.2 | BC6: Zubat | BD6: 44909 | BF6: 0.2 | BH6: Nacli | BI6: 44909 | BK6: 0.2 | BM6: Zubat | BN6: 44909 | BP6: 0.2 | BR6: Bellsprout | BS6: 13-15 | BU6: 0.2 | BW6: Petilil | BX6: 14-16 | BZ6: 0.2 | CB6: Taillow | CC6: 16-18 | CE6: 0.2 | CG6: Hatenna | CH6: 18-20 | CJ6: 0.2 | CL6: Cherubi | CM6: 16-18 | CO6: 0.2 | CQ6: Ducklett | CR6: 23-25 | CT6: 0.2 | CV6: Diglett | CW6: 23-25 | CY6: 0.2 | DA6: Exeggcute | DB6: 25-27 | DD6: 0.2 | DF6: Helioptile | DG6: 27-29 | DI6: 0.2 | DK6: Aron | DL6: 29-31 | DN6: 0.2 | DP6: Boldore | DQ6: 30-32 | DS6: 0.2 | DU6: Inkay | DV6: 36-38 | DX6: 0.2 | DZ6: Minccino | EA6: 33-35 | EC6: 0.2 | EE6: Cofagrigus | EF6: 45-47 | EH6: 0.2 | EJ6: Cofagrigus | EK6: 45-47 | EM6: 0.2 | EO6: Cofagrigus | EP6: 45-47 | ER6: 0.2 | ET6: Cofagrigus | EU6: 45-47 | EW6: 0.2 | EY6: Yanma | EZ6: 36-38 | FB6: 0.2 | FD6: Cyclizar | FE6: 46-48 | FG6: 0.2 | FI6: Vikavolt | FJ6: 49-51 | FL6: 0.2 | FN6: Dewgong | FO6: 50-52 | FQ6: 0.2 | FS6: Exeggutor | FT6: 48-50 | FV6: 0.2 | FX6: Swadloon | FY6: 48-50 | GA6: 0.2 | GC6: Ambipom | GD6: 49-51 | GF6: 0.2 | GH6: Fearow | GI6: 33-35 | GK6: 0.2 | GM6: Snorunt | GN6: 62-64 | GP6: 0.2 | GR6: Darmanitan-Galar | GS6: 62-64 | GU6: 0.2 | GW6: Snover | GX6: 62-64 | GZ6: 0.2 | HB6: Darmanitan-Galar | HC6: 62-64 | HE6: 0.2 | HG6: Abomasnow | HH6: 62-64 | HJ6: 0.2 | HL6: Audino | HM6: 63-65 | HO6: 0.2 | HQ6: Garbodor | HR6: 63-65 | HT6: 0.2 | HV6: Seviper | HW6: 63-65 | HY6: 0.2 | IA6: Garbodor | IB6: 63-65 | ID6: 0.2 | IF6: Electrode | IG6: 63-65 | II6: 0.2 | IK6: Golbat | IL6: 68-70 | IN6: 0.2 | IP6: Great Tusk | IQ6: 68-70 | IS6: 0.2 | IU6: Noivern | IV6: 68-70 | IX6: 0.2 | IZ6: Unown | JA6: 75-77 | JC6: 0.2 | JE6: Unown | JF6: 75-77 | JH6: 0.2 | JJ6: Metagross | JK6: 80-82 | JM6: 0.2 | JO6: Garchomp | JP6: 80-82 | JR6: 0.2 | JT6: Iron Bundle | JU6: 80-82 | JY6: 0.2 | KA6: Smeargle | KB6: 83-85 | KD6: 0.2 | KF6: Coalossal | KG6: 83-85 | KI6: 0.2 | KK6: Magcargo | KL6: 84-85 | KN6: 0.2 | KP6: Sirfetch'd | KQ6: 84-85 | KS6: 0.2 | KU6: Noibat-Sevii | KV6: 84-85 | KX6: 0.2 | KZ6: Blitzle-Sevii | LA6: 84-85 | LC6: 0.2 | LE6: Sneasel-Hisui | LF6: 84-85 | LH6: 0.2 | LJ6: Nymble-Sevii | LK6: 84-85 | LM6: 0.2 | LO6: Zoroark-Hisui | LP6: 84-85 | LR6: 0.2 | LT6: Typhlosion-Hisui | LU6: 84-85 | LW6: 0.2 | LY6: Clauncher-Sevii | LZ6: 84-85
C7: 0.1 | E7: Rattata | F7: 44231 | H7: 0.1 | J7: Poochyena | K7: 44625 | M7: 0.1 | O7: Mankey | P7: 44625 | R7: 0.1 | T7: Wiglett | U7: 45022 | W7: 0.1 | Y7: Ponyta | Z7: 44625 | AB7: 0.1 | AD7: Pikachu | AE7: 44657 | AG7: 0.1 | AI7: Natu | AJ7: 44657 | AL7: 0.1 | AN7: Numel | AO7: 44751 | AQ7: 0.1 | AS7: Exeggcute | AT7: 44751 | AV7: 0.1 | AX7: Spearow | AY7: 44846 | BA7: 0.1 | BC7: Rockruff | BD7: 44909 | BF7: 0.1 | BH7: Rolycoly | BI7: 44909 | BK7: 0.1 | BM7: Pawniard | BN7: 44909 | BP7: 0.1 | BR7: Shinx | BS7: 13-15 | BU7: 0.1 | BW7: Yamper | BX7: 14-16 | BZ7: 0.1 | CB7: Pineco | CC7: 16-18 | CE7: 0.1 | CG7: Solosis | CH7: 18-20 | CJ7: 0.1 | CL7: Gulpin | CM7: 16-18 | CO7: 0.1 | CQ7: Drowzee | CR7: 23-25 | CT7: 0.1 | CV7: Stunfisk | CW7: 23-25 | CY7: 0.1 | DA7: Darumaka | DB7: 25-27 | DD7: 0.1 | DF7: Blitzle | DG7: 27-29 | DI7: 0.1 | DK7: Shuckle | DL7: 29-31 | DN7: 0.1 | DP7: Swinub | DQ7: 30-32 | DS7: 0.1 | DU7: Rufflet | DV7: 36-38 | DX7: 0.1 | DZ7: Vanillite | EA7: 33-35 | EC7: 0.1 | EE7: Dusclops | EF7: 45-47 | EH7: 0.1 | EJ7: Dusclops | EK7: 45-47 | EM7: 0.1 | EO7: Dusclops | EP7: 45-47 | ER7: 0.1 | ET7: Dusclops | EU7: 45-47 | EW7: 0.1 | EY7: Rhyhorn | EZ7: 36-38 | FB7: 0.1 | FD7: Muk | FE7: 46-48 | FG7: 0.1 | FI7: Poliwrath | FJ7: 49-51 | FL7: 0.1 | FN7: Walrein | FO7: 50-52 | FQ7: 0.1 | FS7: Roselia | FT7: 48-50 | FV7: 0.1 | FX7: Torkoal | FY7: 48-50 | GA7: 0.1 | GC7: Tsareena | GD7: 49-51 | GF7: 0.1 | GH7: Simisage | GI7: 33-35 | GK7: 0.1 | GM7: Beartic | GN7: 62-64 | GP7: 0.1 | GR7: Vanilluxe | GS7: 62-64 | GU7: 0.1 | GW7: Ninetales-Alola | GX7: 62-64 | GZ7: 0.1 | HB7: Ninetales-Alola | HC7: 62-64 | HE7: 0.1 | HG7: Ninetales-Alola | HH7: 62-64 | HJ7: 0.1 | HL7: Muk | HM7: 63-65 | HO7: 0.1 | HQ7: Weezing | HR7: 63-65 | HT7: 0.1 | HV7: Ariados | HW7: 63-65 | HY7: 0.1 | IA7: Ariados | IB7: 63-65 | ID7: 0.1 | IF7: Zebstrika | IG7: 63-65 | II7: 0.1 | IK7: Machamp | IL7: 68-70 | IN7: 0.1 | IP7: Primeape | IQ7: 68-70 | IS7: 0.1 | IU7: Medicham | IV7: 68-70 | IX7: 0.1 | IZ7: Meganium | JA7: 75-77 | JC7: 0.1 | JE7: Cinderace | JF7: 75-77 | JH7: 0.1 | JJ7: Goodra | JK7: 80-82 | JM7: 0.1 | JO7: Tyranitar | JP7: 80-82 | JR7: 0.1 | JT7: Dragapult | JU7: 80-82 | JY7: 0.1 | KA7: Alcremie-Strbrry | KB7: 83-85 | KD7: 0.1 | KF7: Darmanitan | KG7: 83-85 | KI7: 0.1 | KK7: Ninetales | KL7: 84-85 | KN7: 0.1 | KP7: Lilligant | KQ7: 84-85 | KS7: 0.1 | KU7: Copperajah | KV7: 84-85 | KX7: 0.1 | KZ7: Lilligant-Hisui | LA7: 84-85 | LC7: 0.1 | LE7: Hatterene | LF7: 84-85 | LH7: 0.1 | LJ7: Decidueye-Hisui | LK7: 84-85 | LM7: 0.1 | LO7: Ursaluna-BM | LP7: 84-85 | LR7: 0.1 | LT7: Flutter Mane | LU7: 83-85 | LW7: 0.1 | LY7: Goodra-Hisui | LZ7: 84-85
C8: 0.1 | E8: Mienfoo | F8: 44231 | H8: 0.1 | J8: Spearow | K8: 44625 | M8: 0.1 | O8: Morelull | P8: 44625 | R8: 0.1 | T8: Wiglett | U8: 45022 | W8: 0.1 | Y8: Phanpy | Z8: 44625 | AB8: 0.1 | AD8: Burmy-Sandy | AE8: 44657 | AG8: 0.1 | AI8: Burmy | AJ8: 44657 | AL8: 0.1 | AN8: Yamask | AO8: 44751 | AQ8: 0.1 | AS8: Spoink | AT8: 44751 | AV8: 0.1 | AX8: Nidoran-M | AY8: 44846 | BA8: 0.1 | BC8: Timburr | BD8: 44909 | BF8: 0.1 | BH8: Slugma | BI8: 44909 | BK8: 0.1 | BM8: Numel | BN8: 44909 | BP8: 0.1 | BR8: Pachirisu | BS8: 13-15 | BU8: 0.1 | BW8: Charcadet | BX8: 14-16 | BZ8: 0.1 | CB8: Tadbulb | CC8: 16-18 | CE8: 0.1 | CG8: Growlithe | CH8: 18-20 | CJ8: 0.1 | CL8: Furfrou | CM8: 16-18 | CO8: 0.1 | CQ8: Baltoy | CR8: 23-25 | CT8: 0.1 | CV8: Silicobra | CW8: 23-25 | CY8: 0.1 | DA8: Dewpider | DB8: 25-27 | DD8: 0.1 | DF8: Pincurchin | DG8: 27-29 | DI8: 0.1 | DK8: Solrock | DL8: 29-31 | DN8: 0.1 | DP8: Snorunt | DQ8: 30-32 | DS8: 0.1 | DU8: Rufflet | DV8: 36-38 | DX8: 0.1 | DZ8: Bouffalant | EA8: 33-35 | EC8: 0.1 | EE8: Mismagius | EF8: 45-47 | EH8: 0.1 | EJ8: Mismagius | EK8: 45-47 | EM8: 0.1 | EO8: Annihilape | EP8: 45-47 | ER8: 0.1 | ET8: Mismagius | EU8: 45-47 | EW8: 0.1 | EY8: Skorupi | EZ8: 36-38 | FB8: 0.1 | FD8: Zebstrika | FE8: 46-48 | FG8: 0.1 | FI8: Abomasnow | FJ8: 49-51 | FL8: 0.1 | FN8: Glalie | FO8: 50-52 | FQ8: 0.1 | FS8: Lurantis | FT8: 48-50 | FV8: 0.1 | FX8: Torkoal | FY8: 48-50 | GA8: 0.1 | GC8: Galvantula | GD8: 49-51 | GF8: 0.1 | GH8: Simisear | GI8: 33-35 | GK8: 0.1 | GM8: Beartic | GN8: 62-64 | GP8: 0.1 | GR8: Vanilluxe | GS8: 62-64 | GU8: 0.1 | GW8: Ninetales-Alola | GX8: 62-64 | GZ8: 0.1 | HB8: Ninetales-Alola | HC8: 62-64 | HE8: 0.1 | HG8: Ninetales-Alola | HH8: 62-64 | HJ8: 0.1 | HL8: Muk | HM8: 63-65 | HO8: 0.1 | HQ8: Swalot | HR8: 63-65 | HT8: 0.1 | HV8: Ariados | HW8: 63-65 | HY8: 0.1 | IA8: Ariados | IB8: 63-65 | ID8: 0.1 | IF8: Eelektross | IG8: 63-65 | II8: 0.1 | IK8: Machamp | IL8: 68-70 | IN8: 0.1 | IP8: Primeape | IQ8: 68-70 | IS8: 0.1 | IU8: Medicham | IV8: 68-70 | IX8: 0.1 | IZ8: Meganium | JA8: 75-77 | JC8: 0.1 | JE8: Cinderace | JF8: 75-77 | JH8: 0.1 | JJ8: Steelix | JK8: 80-82 | JM8: 0.1 | JO8: Machamp | JP8: 80-82 | JR8: 0.1 | JT8: Mawile | JU8: 80-82 | JY8: 0.1 | KA8: Alcremie-Strbrry | KB8: 83-85 | KD8: 0.1 | KF8: Darmanitan | KG8: 83-85 | KI8: 0.1 | KK8: Ninetales | KL8: 84-85 | KN8: 0.1 | KP8: Lilligant | KQ8: 84-85 | KS8: 0.1 | KU8: Copperajah | KV8: 84-85 | KX8: 0.1 | KZ8: Lilligant-Hisui | LA8: 84-85 | LC8: 0.1 | LE8: Hatterene | LF8: 84-85 | LH8: 0.1 | LJ8: Decidueye-Hisui | LK8: 84-85 | LM8: 0.1 | LO8: Ursaluna-BM | LP8: 84-85 | LR8: 0.1 | LT8: Flutter Mane | LU8: 83-85 | LW8: 0.1 | LY8: Goodra-Hisui | LZ8: 84-85
C9: 0.1 | E9: Meowth | F9: 44231 | H9: 0.1 | J9: Patrat | K9: 44625 | M9: 0.1 | O9: Snubbull | P9: 44625 | R9: 0.1 | T9: Dwebble | U9: 45022 | W9: 0.1 | Y9: Meditite | Z9: 44625 | AB9: 0.1 | AD9: Sewaddle | AE9: 44657 | AG9: 0.1 | AI9: Combee | AJ9: 44657 | AL9: 0.1 | AN9: Sandshrew | AO9: 44751 | AQ9: 0.1 | AS9: Hoppip | AT9: 44751 | AV9: 0.1 | AX9: Nickit | AY9: 44846 | BA9: 0.1 | BC9: Woobat | BD9: 44909 | BF9: 0.1 | BH9: Torkoal | BI9: 44909 | BK9: 0.1 | BM9: Cranidos | BN9: 44909 | BP9: 0.1 | BR9: Glameow | BS9: 13-15 | BU9: 0.1 | BW9: Elekid | BX9: 14-16 | BZ9: 0.1 | CB9: Karrablast | CC9: 16-18 | CE9: 0.1 | CG9: Swirlix | CH9: 18-20 | CJ9: 0.1 | CL9: Sizzlipede | CM9: 16-18 | CO9: 0.1 | CQ9: Maractus | CR9: 23-25 | CT9: 0.1 | CV9: Golett | CW9: 23-25 | CY9: 0.1 | DA9: Indeedee | DB9: 25-27 | DD9: 0.1 | DF9: Plusle | DG9: 27-29 | DI9: 0.1 | DK9: Carkol | DL9: 29-31 | DN9: 0.1 | DP9: Bronzor | DQ9: 30-32 | DS9: 0.1 | DU9: Cutiefly | DV9: 36-38 | DX9: 0.1 | DZ9: Bouffalant | EA9: 33-35 | EC9: 0.1 | EE9: Mismagius | EF9: 45-47 | EH9: 0.1 | EJ9: Mismagius | EK9: 45-47 | EM9: 0.1 | EO9: Annihilape | EP9: 45-47 | ER9: 0.1 | ET9: Mismagius | EU9: 45-47 | EW9: 0.1 | EY9: Cufant | EZ9: 36-38 | FB9: 0.1 | FD9: Grumpig | FE9: 46-48 | FG9: 0.1 | FI9: Altaria | FJ9: 49-51 | FL9: 0.1 | FN9: Throh | FO9: 50-52 | FQ9: 0.1 | FS9: Simisage | FT9: 48-50 | FV9: 0.1 | FX9: Whirlipede | FY9: 48-50 | GA9: 0.1 | GC9: Simipour | GD9: 49-51 | GF9: 0.1 | GH9: Simipour | GI9: 33-35 | GK9: 0.1 | GM9: Slowbro | GN9: 62-64 | GP9: 0.1 | GR9: Slowking | GS9: 62-64 | GU9: 0.1 | GW9: Crawdaunt | GX9: 62-64 | GZ9: 0.1 | HB9: Dewgong | HC9: 62-64 | HE9: 0.1 | HG9: Dewgong | HH9: 62-64 | HJ9: 0.1 | HL9: Weezing | HM9: 63-65 | HO9: 0.1 | HQ9: Heatmor | HR9: 63-65 | HT9: 0.1 | HV9: Rapidash | HW9: 63-65 | HY9: 0.1 | IA9: Magmar | IB9: 63-65 | ID9: 0.1 | IF9: Ampharos | IG9: 63-65 | II9: 0.1 | IK9: Magneton | IL9: 68-70 | IN9: 0.1 | IP9: Great Tusk | IQ9: 68-70 | IS9: 0.1 | IU9: Lopunny | IV9: 68-70 | IX9: 0.1 | IZ9: Quaquaval | JA9: 75-77 | JC9: 0.1 | JE9: Typhlosion | JF9: 63-65 | JH9: 0.1 | JJ9: Audino | JK9: 80-82 | JM9: 0.1 | JO9: Medicham | JP9: 80-82 | JR9: 0.1 | JT9: Mawile | JU9: 80-82 | JY9: 0.1 | KA9: Centiskorch | KB9: 83-85 | KD9: 0.1 | KF9: Pyroar | KG9: 83-85 | KI9: 0.1 | KK9: Pyroar | KL9: 84-85 | KN9: 0.1 | KP9: Flygon | KQ9: 84-85 | KS9: 0.1 | KU9: Stunfisk-Galar | KV9: 84-85 | KX9: 0.1 | KZ9: Slowbro-Galar | LA9: 84-85 | LC9: 0.1 | LE9: Crustle | LF9: 84-85 | LH9: 0.1 | LJ9: Pinsir | LK9: 84-85 | LM9: 0.1 | LO9: Mimikyu | LP9: 84-85 | LR9: 0.1 | LT9: Spiritomb | LU9: 84-85 | LW9: 0.1 | LY9: Samurott-Hisui | LZ9: 84-85
C10: 0.1 | E10: Yungoos | F10: 44231 | H10: 0.1 | J10: Cubchoo | K10: 44657 | M10: 0.1 | O10: Lillipup | P10: 44625 | R10: 0.1 | T10: Snubbull | U10: 45022 | W10: 0.1 | Y10: Shinx | Z10: 44625 | AB10: 0.1 | AD10: Scatterbug | AE10: 44657 | AG10: 0.1 | AI10: Kricketot | AJ10: 44657 | AL10: 0.1 | AN10: Geodude | AO10: 44751 | AQ10: 0.1 | AS10: Numel | AT10: 44751 | AV10: 0.1 | AX10: Shroomish | AY10: 44846 | BA10: 0.1 | BC10: Chewtle | BD10: 44909 | BF10: 0.1 | BH10: Teddiursa | BI10: 44909 | BK10: 0.1 | BM10: Drilbur | BN10: 44909 | BP10: 0.1 | BR10: Tandemaus | BS10: 13-15 | BU10: 0.1 | BW10: Volbeat | BX10: 14-16 | BZ10: 0.1 | CB10: Doduo | CC10: 16-18 | CE10: 0.1 | CG10: Morelull | CH10: 18-20 | CJ10: 0.1 | CL10: Dedenne | CM10: 16-18 | CO10: 0.1 | CQ10: Bunnelby | CR10: 23-25 | CT10: 0.1 | CV10: Sandile | CW10: 23-25 | CY10: 0.1 | DA10: Rufflet | DB10: 25-27 | DD10: 0.1 | DF10: Skitty | DG10: 27-29 | DI10: 0.1 | DK10: Carbink | DL10: 29-31 | DN10: 0.1 | DP10: Bonsly | DQ10: 30-32 | DS10: 0.1 | DU10: Applin | DV10: 36-38 | DX10: 0.1 | DZ10: Venipede | EA10: 33-35 | EC10: 0.1 | EE10: Cubone | EF10: 45-47 | EH10: 0.1 | EJ10: Cubone | EK10: 45-47 | EM10: 0.1 | EO10: Cubone | EP10: 45-47 | ER10: 0.1 | ET10: Cubone | EU10: 45-47 | EW10: 0.1 | EY10: Durant | EZ10: 36-38 | FB10: 0.1 | FD10: Torkoal | FE10: 46-48 | FG10: 0.1 | FI10: Parasect | FJ10: 49-51 | FL10: 0.1 | FN10: Cetitan | FO10: 50-52 | FQ10: 0.1 | FS10: Jumpluff | FT10: 48-50 | FV10: 0.1 | FX10: Whirlipede | FY10: 48-50 | GA10: 0.1 | GC10: Oricorio | GD10: 49-51 | GF10: 0.1 | GH10: Simipour | GI10: 33-35 | GK10: 0.1 | GM10: Slowbro | GN10: 62-64 | GP10: 0.1 | GR10: Slowking | GS10: 62-64 | GU10: 0.1 | GW10: Crawdaunt | GX10: 62-64 | GZ10: 0.1 | HB10: Dewgong | HC10: 62-64 | HE10: 0.1 | HG10: Dewgong | HH10: 62-64 | HJ10: 0.1 | HL10: Liepard | HM10: 63-65 | HO10: 0.1 | HQ10: Salazzle | HR10: 63-65 | HT10: 0.1 | HV10: Skuntank | HW10: 63-65 | HY10: 0.1 | IA10: Mightyena | IB10: 63-65 | ID10: 0.1 | IF10: Ampharos | IG10: 63-65 | II10: 0.1 | IK10: Magneton | IL10: 68-70 | IN10: 0.1 | IP10: Audino | IQ10: 68-70 | IS10: 0.1 | IU10: Iron Treads | IV10: 68-70 | IX10: 0.1 | IZ10: Quaquaval | JA10: 75-77 | JC10: 0.1 | JE10: Typhlosion | JF10: 63-65 | JH10: 0.1 | JJ10: Salamence | JK10: 80-82 | JM10: 0.1 | JO10: Lucario | JP10: 80-82 | JR10: 0.1 | JT10: Toxtricity | JU10: 80-82 | JY10: 0.1 | KA10: Centiskorch | KB10: 83-85 | KD10: 0.1 | KF10: Dodrio-Sevii | KG10: 83-85 | KI10: 0.1 | KK10: Pyroar | KL10: 83-85 | KN10: 0.1 | KP10: Flygon | KQ10: 83-85 | KS10: 0.1 | KU10: Stunfisk-Galar | KV10: 83-85 | KX10: 0.1 | KZ10: Slowbro-Galar | LA10: 83-85 | LC10: 0.1 | LE10: Crustle | LF10: 83-85 | LH10: 0.1 | LJ10: Pinsir | LK10: 83-85 | LM10: 0.1 | LO10: Mimikyu | LP10: 83-85 | LR10: 0.1 | LT10: Spiritomb | LU10: 83-85 | LW10: 0.1 | LY10: Samurott-Hisui | LZ10: 83-85
C11: 0.05 | E11: Pidgey | F11: 44260 | H11: 0.05 | J11: Deerling-Summer | K11: 44625 | M11: 0.05 | O11: Oddish | P11: 44625 | R11: 0.05 | T11: Wingull | U11: 45022 | W11: 0.05 | Y11: Mareep | Z11: 44625 | AB11: 0.05 | AD11: Ledyba | AE11: 44657 | AG11: 0.05 | AI11: Slakoth | AJ11: 44657 | AL11: 0.05 | AN11: Trapinch | AO11: 44751 | AQ11: 0.05 | AS11: Cutiefly | AT11: 44751 | AV11: 0.05 | AX11: Buneary | AY11: 44846 | BA11: 0.05 | BC11: Makuhita | BD11: 44909 | BF11: 0.05 | BH11: Tinkatink | BI11: 44909 | BK11: 0.05 | BM11: Mudbray | BN11: 44909 | BP11: 0.05 | BR11: Pumpkaboo | BS11: 13-15 | BU11: 0.05 | BW11: Marill | BX11: 14-16 | BZ11: 0.05 | CB11: Aipom | CC11: 16-18 | CE11: 0.05 | CG11: Vulpix | CH11: 18-20 | CJ11: 0.05 | CL11: Lickitung | CM11: 16-18 | CO11: 0.05 | CQ11: Crabrawler | CR11: 23-25 | CT11: 0.05 | CV11: Drilbur | CW11: 23-25 | CY11: 0.05 | DA11: Mime Jr. | DB11: 25-27 | DD11: 0.05 | DF11: Tadbulb | DG11: 27-29 | DI11: 0.05 | DK11: Minior | DL11: 29-31 | DN11: 0.05 | DP11: Cetoddle | DQ11: 30-32 | DS11: 0.05 | DU11: Passimian | DV11: 36-38 | DX11: 0.05 | DZ11: Comfey | EA11: 33-35 | EC11: 0.05 | EE11: Spiritomb | EF11: 45-47 | EH11: 0.05 | EJ11: Spiritomb | EK11: 45-47 | EM11: 0.05 | EO11: Spiritomb | EP11: 45-47 | ER11: 0.05 | ET11: Spiritomb | EU11: 45-47 | EW11: 0.05 | EY11: Togedemaru | EZ11: 36-38 | FB11: 0.05 | FD11: Skarmory | FE11: 46-48 | FG11: 0.05 | FI11: Toxicroak | FJ11: 49-51 | FL11: 0.05 | FN11: Avalugg | FO11: 50-52 | FQ11: 0.05 | FS11: Bulbasaur | FT11: 48-50 | FV11: 0.05 | FX11: Charjabug | FY11: 48-50 | GA11: 0.05 | GC11: Sigilyph | GD11: 49-51 | GF11: 0.05 | GH11: Seviper | GI11: 33-35 | GK11: 0.05 | GM11: Golbat | GN11: 62-64 | GP11: 0.05 | GR11: Golbat | GS11: 62-64 | GU11: 0.05 | GW11: Golbat | GX11: 62-64 | GZ11: 0.05 | HB11: Golbat | HC11: 62-64 | HE11: 0.05 | HG11: Crawdaunt | HH11: 62-64 | HJ11: 0.05 | HL11: Arcanine | HM11: 63-65 | HO11: 0.05 | HQ11: Houndoom | HR11: 63-65 | HT11: 0.05 | HV11: Armarouge | HW11: 63-65 | HY11: 0.05 | IA11: Arcanine | IB11: 63-65 | ID11: 0.05 | IF11: Dedenne | IG11: 63-65 | II11: 0.05 | IK11: Seismitoad | IL11: 68-70 | IN11: 0.05 | IP11: Alakazam | IQ11: 68-70 | IS11: 0.05 | IU11: Lopunny | IV11: 68-70 | IX11: 0.05 | IZ11: Empoleon | JA11: 75-77 | JC11: 0.05 | JE11: Blaziken | JF11: 75-77 | JH11: 0.05 | JJ11: Volcarona | JK11: 80-82 | JM11: 0.05 | JO11: Lucario | JP11: 80-82 | JR11: 0.05 | JT11: Scizor | JU11: 80-82 | JY11: 0.05 | KA11: Gardevoir | KB11: 83-85 | KD11: 0.05 | KF11: Arcanine | KG11: 83-85 | KI11: 0.05 | KK11: Darmanitan | KL11: 83-85 | KN11: 0.05 | KP11: Klefki | KQ11: 83-85 | KS11: 0.05 | KU11: Arcanine-Hisui | KV11: 83-85 | KX11: 0.05 | KZ11: Morpeko | LA11: 83-85 | LC11: 0.05 | LE11: Braviary-Hisui | LF11: 83-85 | LH11: 0.05 | LJ11: Indeedee | LK11: 83-85 | LM11: 0.05 | LO11: Flutter Mane | LP11: 83-85 | LR11: 0.05 | LT11: Dragapult | LU11: 83-85 | LW11: 0.05 | LY11: Sandaconda | LZ11: 83-85
C12: 0.05 | E12: Pidgey | F12: 44260 | H12: 0.05 | J12: Greavard | K12: 44625 | M12: 0.05 | O12: Sandygast | P12: 44625 | R12: 0.05 | T12: Wingull | U12: 45022 | W12: 0.05 | Y12: Litleo | Z12: 44657 | AB12: 0.05 | AD12: Surskit | AE12: 44657 | AG12: 0.05 | AI12: Grubbin | AJ12: 44657 | AL12: 0.05 | AN12: Silicobra | AO12: 44751 | AQ12: 0.05 | AS12: Sinistea | AT12: 44751 | AV12: 0.05 | AX12: Buneary | AY12: 44846 | BA12: 0.05 | BC12: Makuhita | BD12: 44909 | BF12: 0.05 | BH12: Baltoy | BI12: 44909 | BK12: 0.05 | BM12: Smoochum | BN12: 44909 | BP12: 0.05 | BR12: Flabébé | BS12: 13-15 | BU12: 0.05 | BW12: Farfetch'd | BX12: 14-16 | BZ12: 0.05 | CB12: Whismur | CC12: 16-18 | CE12: 0.05 | CG12: Solosis | CH12: 18-20 | CJ12: 0.05 | CL12: Lickitung | CM12: 16-18 | CO12: 0.05 | CQ12: Crabrawler | CR12: 23-25 | CT12: 0.05 | CV12: Gligar | CW12: 23-25 | CY12: 0.05 | DA12: Mime Jr. | DB12: 25-27 | DD12: 0.05 | DF12: Tadbulb | DG12: 27-29 | DI12: 0.05 | DK12: Ferroseed | DL12: 29-31 | DN12: 0.05 | DP12: Cetoddle | DQ12: 30-32 | DS12: 0.05 | DU12: Passimian | DV12: 36-38 | DX12: 0.05 | DZ12: Comfey | EA12: 33-35 | EC12: 0.05 | EE12: Sableye | EF12: 45-47 | EH12: 0.05 | EJ12: Sableye | EK12: 45-47 | EM12: 0.05 | EO12: Sableye | EP12: 45-47 | ER12: 0.05 | ET12: Sableye | EU12: 45-47 | EW12: 0.05 | EY12: Skarmory | EZ12: 36-38 | FB12: 0.05 | FD12: Skarmory | FE12: 46-48 | FG12: 0.05 | FI12: Toxicroak | FJ12: 49-51 | FL12: 0.05 | FN12: Avalugg | FO12: 50-52 | FQ12: 0.05 | FS12: Bulbasaur | FT12: 48-50 | FV12: 0.05 | FX12: Charjabug | FY12: 48-50 | GA12: 0.05 | GC12: Sigilyph | GD12: 49-51 | GF12: 0.05 | GH12: Seviper | GI12: 33-35 | GK12: 0.05 | GM12: Golbat | GN12: 62-64 | GP12: 0.05 | GR12: Golbat | GS12: 62-64 | GU12: 0.05 | GW12: Golbat | GX12: 62-64 | GZ12: 0.05 | HB12: Golbat | HC12: 62-64 | HE12: 0.05 | HG12: Crawdaunt | HH12: 62-64 | HJ12: 0.05 | HL12: Arcanine | HM12: 63-65 | HO12: 0.05 | HQ12: Houndoom | HR12: 63-65 | HT12: 0.05 | HV12: Armarouge | HW12: 63-65 | HY12: 0.05 | IA12: Arcanine | IB12: 63-65 | ID12: 0.05 | IF12: Dedenne | IG12: 63-65 | II12: 0.05 | IK12: Seismitoad | IL12: 68-70 | IN12: 0.05 | IP12: Alakazam | IQ12: 68-70 | IS12: 0.05 | IU12: Gardevoir | IV12: 68-70 | IX12: 0.05 | IZ12: Empoleon | JA12: 75-77 | JC12: 0.05 | JE12: Blaziken | JF12: 75-77 | JH12: 0.05 | JJ12: Aegislash | JK12: 80-82 | JM12: 0.05 | JO12: Medicham | JP12: 80-82 | JR12: 0.05 | JT12: Aerodactyl | JU12: 80-82 | JY12: 0.05 | KA12: Gardevoir | KB12: 83-85 | KD12: 0.05 | KF12: Arcanine | KG12: 83-85 | KI12: 0.05 | KK12: Darmanitan | KL12: 83-85 | KN12: 0.05 | KP12: Klefki | KQ12: 83-85 | KS12: 0.05 | KU12: Arcanine-Hisui | KV12: 83-85 | KX12: 0.05 | KZ12: Morpeko | LA12: 83-85 | LC12: 0.05 | LE12: Braviary-Hisui | LF12: 83-85 | LH12: 0.05 | LJ12: Indeedee | LK12: 83-85 | LM12: 0.05 | LO12: Flutter Mane | LP12: 83-85 | LR12: 0.05 | LT12: Dragapult | LU12: 83-85 | LW12: 0.05 | LY12: Sandaconda | LZ12: 83-85
C13: 0.04 | E13: Smoliv | F13: 44231 | H13: 0.04 | J13: Pikipek | K13: 44625 | M13: 0.04 | O13: Bellsprout | P13: 44625 | R13: 0.04 | T13: Fidough | U13: 45022 | W13: 0.04 | Y13: Zigzagoon | Z13: 44625 | AB13: 0.04 | AD13: Shroomish | AE13: 44657 | AG13: 0.04 | AI13: Bramblin | AJ13: 44657 | AL13: 0.04 | AN13: Bronzor | AO13: 44751 | AQ13: 0.04 | AS13: Ekans | AT13: 44751 | AV13: 0.04 | AX13: Litleo | AY13: 44846 | BA13: 0.04 | BC13: Tyrogue | BD13: 44909 | BF13: 0.04 | BH13: Shuppet | BI13: 44909 | BK13: 0.04 | BM13: Smoochum | BN13: 44909 | BP13: 0.04 | BR13: Pumpkaboo-Sm | BS13: 13-15 | BU13: 0.04 | BW13: Ralts | BX13: 14-16 | BZ13: 0.04 | CB13: Squawkabilly-G | CC13: 16-18 | CE13: 0.04 | CG13: Grimer | CH13: 18-20 | CJ13: 0.04 | CL13: Flittle | CM13: 16-18 | CO13: 0.04 | CQ13: Flamigo | CR13: 23-25 | CT13: 0.04 | CV13: Golett | CW13: 23-25 | CY13: 0.04 | DA13: Tropius | DB13: 25-27 | DD13: 0.04 | DF13: Magnemite | DG13: 27-29 | DI13: 0.04 | DK13: Stonjourner | DL13: 29-31 | DN13: 0.04 | DP13: Cubchoo | DQ13: 30-32 | DS13: 0.04 | DU13: Mienfoo | DV13: 36-38 | DX13: 0.04 | DZ13: Girafarig | EA13: 33-35 | EC13: 0.04 | EE13: Polteageist | EF13: 45-47 | EH13: 0.04 | EJ13: Houndstone | EK13: 45-47 | EM13: 0.04 | EO13: Polteageist | EP13: 45-47 | ER13: 0.04 | ET13: Polteageist | EU13: 45-47 | EW13: 0.04 | EY13: Orthworm | EZ13: 36-38 | FB13: 0.04 | FD13: Drampa | FE13: 46-48 | FG13: 0.04 | FI13: Kabutops | FJ13: 49-51 | FL13: 0.04 | FN13: Mr. Mime-Galar | FO13: 50-52 | FQ13: 0.04 | FS13: Exeggutor-Alola | FT13: 48-50 | FV13: 0.04 | FX13: Durant | FY13: 48-50 | GA13: 0.04 | GC13: Ferrothorn | GD13: 49-51 | GF13: 0.04 | GH13: Golbat | GI13: 33-35 | GK13: 0.04 | GM13: Avalugg | GN13: 62-64 | GP13: 0.04 | GR13: Cryogonal | GS13: 62-64 | GU13: 0.04 | GW13: Sneasel | GX13: 62-64 | GZ13: 0.04 | HB13: Frosmoth | HC13: 62-64 | HE13: 0.04 | HG13: Golbat | HH13: 62-64 | HJ13: 0.04 | HL13: Sableye | HM13: 63-65 | HO13: 0.04 | HQ13: Banette | HR13: 63-65 | HT13: 0.04 | HV13: Krookodile | HW13: 63-65 | HY13: 0.04 | IA13: Banette | IB13: 63-65 | ID13: 0.04 | IF13: Electabuzz | IG13: 63-65 | II13: 0.04 | IK13: Duraludon | IL13: 68-70 | IN13: 0.04 | IP13: Duraludon | IQ13: 68-70 | IS13: 0.04 | IU13: Excadrill | IV13: 68-70 | IX13: 0.04 | IZ13: Mismagius | JA13: 75-77 | JC13: 0.04 | JE13: Morpeko | JF13: 75-77 | JH13: 0.04 | JJ13: Marowak | JK13: 80-82 | JM13: 0.04 | JO13: Kommo-o | JP13: 80-82 | JR13: 0.04 | JT13: Aerodactyl | JU13: 80-82 | JY13: 0.04 | KA13: Seviper | KB13: 83-85 | KD13: 0.04 | KF13: Volcarona | KG13: 83-85 | KI13: 0.04 | KK13: Arcanine-Hisui | KL13: 83-85 | KN13: 0.04 | KP13: Kingler | KQ13: 83-85 | KS13: 0.04 | KU13: Great Tusk | KV13: 83-85 | KX13: 0.04 | KZ13: Grapploct | LA13: 83-85 | LC13: 0.04 | LE13: Gliscor | LF13: 83-85 | LH13: 0.04 | LJ13: Roserade | LK13: 83-85 | LM13: 0.04 | LO13: Polteageist | LP13: 83-85 | LR13: 0.04 | LT13: Cursola | LU13: 83-85 | LW13: 0.04 | LY13: Smeargle | LZ13: 83-85
C14: 0.04 | E14: Smoliv | F14: 44231 | H14: 0.04 | J14: Pikipek | K14: 44625 | M14: 0.04 | O14: Rockruff | P14: 44625 | R14: 0.04 | T14: Fidough | U14: 45022 | W14: 0.04 | Y14: Abra | Z14: 44625 | AB14: 0.04 | AD14: Shroomish | AE14: 44657 | AG14: 0.04 | AI14: Pumpkaboo-Su | AJ14: 44657 | AL14: 0.04 | AN14: Machop | AO14: 44751 | AQ14: 0.04 | AS14: Phanpy | AT14: 44751 | AV14: 0.04 | AX14: Stunky | AY14: 44846 | BA14: 0.04 | BC14: Clefairy | BD14: 44909 | BF14: 0.04 | BH14: Shuppet | BI14: 44909 | BK14: 0.04 | BM14: Solrock | BN14: 44909 | BP14: 0.04 | BR14: Pumpkaboo-Sm | BS14: 13-15 | BU14: 0.04 | BW14: Abra | BX14: 14-16 | BZ14: 0.04 | CB14: Audino | CC14: 16-18 | CE14: 0.04 | CG14: Grimer | CH14: 18-20 | CJ14: 0.04 | CL14: Flittle | CM14: 16-18 | CO14: 0.04 | CQ14: Flamigo | CR14: 23-25 | CT14: 0.04 | CV14: Dugtrio | CW14: 23-25 | CY14: 0.04 | DA14: Tropius | DB14: 25-27 | DD14: 0.04 | DF14: Magnemite | DG14: 27-29 | DI14: 0.04 | DK14: Heatmor | DL14: 29-31 | DN14: 0.04 | DP14: Cubchoo | DQ14: 30-32 | DS14: 0.04 | DU14: Mienfoo | DV14: 36-38 | DX14: 0.04 | DZ14: Girafarig | EA14: 33-35 | EC14: 0.04 | EE14: Polteageist | EF14: 45-47 | EH14: 0.04 | EJ14: Houndstone | EK14: 45-47 | EM14: 0.04 | EO14: Polteageist | EP14: 45-47 | ER14: 0.04 | ET14: Polteageist | EU14: 45-47 | EW14: 0.04 | EY14: Orthworm | EZ14: 36-38 | FB14: 0.04 | FD14: Drampa | FE14: 46-48 | FG14: 0.04 | FI14: Kabutops | FJ14: 49-51 | FL14: 0.04 | FN14: Mr. Mime-Galar | FO14: 50-52 | FQ14: 0.04 | FS14: Duraludon | FT14: 48-50 | FV14: 0.04 | FX14: Durant | FY14: 48-50 | GA14: 0.04 | GC14: Ferrothorn | GD14: 49-51 | GF14: 0.04 | GH14: Golbat | GI14: 33-35 | GK14: 0.04 | GM14: Avalugg | GN14: 62-64 | GP14: 0.04 | GR14: Cryogonal | GS14: 62-64 | GU14: 0.04 | GW14: Sneasel | GX14: 62-64 | GZ14: 0.04 | HB14: Frosmoth | HC14: 62-64 | HE14: 0.04 | HG14: Golbat | HH14: 62-64 | HJ14: 0.04 | HL14: Sableye | HM14: 63-65 | HO14: 0.04 | HQ14: Banette | HR14: 63-65 | HT14: 0.04 | HV14: Krookodile | HW14: 63-65 | HY14: 0.04 | IA14: Banette | IB14: 63-65 | ID14: 0.04 | IF14: Electabuzz | IG14: 63-65 | II14: 0.04 | IK14: Duraludon | IL14: 68-70 | IN14: 0.04 | IP14: Duraludon | IQ14: 68-70 | IS14: 0.04 | IU14: Excadrill | IV14: 68-70 | IX14: 0.04 | IZ14: Mismagius | JA14: 75-77 | JC14: 0.04 | JE14: Morpeko | JF14: 75-77 | JH14: 0.04 | JJ14: Salamence | JK14: 80-82 | JM14: 0.04 | JO14: Kommo-o | JP14: 80-82 | JR14: 0.04 | JT14: Dragapult | JU14: 80-82 | JY14: 0.04 | KA14: Seviper | KB14: 83-85 | KD14: 0.04 | KF14: Volcarona | KG14: 83-85 | KI14: 0.04 | KK14: Arcanine-Hisui | KL14: 83-85 | KN14: 0.04 | KP14: Kingler | KQ14: 83-85 | KS14: 0.04 | KU14: Great Tusk | KV14: 83-85 | KX14: 0.04 | KZ14: Grapploct | LA14: 83-85 | LC14: 0.04 | LE14: Gliscor | LF14: 83-85 | LH14: 0.04 | LJ14: Roserade | LK14: 83-85 | LM14: 0.04 | LO14: Sinistcha | LP14: 83-85 | LR14: 0.04 | LT14: Cursola | LU14: 83-85 | LW14: 0.04 | LY14: Smeargle | LZ14: 83-85
C15: 0.01 | E15: Pansear | F15: 44231 | H15: 0.01 | J15: Snover | K15: 44625 | M15: 0.01 | O15: Panpour | P15: 44625 | R15: 0.01 | T15: Capsakid | U15: 45022 | W15: 0.01 | Y15: Pansage | Z15: 44625 | AB15: 0.01 | AD15: Joltik | AE15: 44688 | AG15: 0.01 | AI15: Nymble | AJ15: 44688 | AL15: 0.01 | AN15: Noibat | AO15: 44751 | AQ15: 0.01 | AS15: Axew | AT15: 44751 | AV15: 0.01 | AX15: Jigglypuff | AY15: 44846 | BA15: 0.01 | BC15: Elgyem | BD15: 44909 | BF15: 0.01 | BH15: Tinkatink | BI15: 44909 | BK15: 0.01 | BM15: Onix | BN15: 44909 | BP15: 0.01 | BR15: Yanma | BS15: 13-15 | BU15: 0.01 | BW15: Klawf | BX15: 14-16 | BZ15: 0.01 | CB15: Zangoose | CC15: 16-18 | CE15: 0.01 | CG15: Drifloon | CH15: 18-20 | CJ15: 0.01 | CL15: Togepi | CM15: 16-18 | CO15: 0.01 | CQ15: Sigilyph | CR15: 23-25 | CT15: 0.01 | CV15: Hippopotas | CW15: 23-25 | CY15: 0.01 | DA15: Skorupi | DB15: 25-27 | DD15: 0.01 | DF15: Sneasel-Hisui | DG15: 27-29 | DI15: 0.01 | DK15: Durant | DL15: 29-31 | DN15: 0.01 | DP15: Glimmet | DQ15: 30-32 | DS15: 0.01 | DU15: Porygon | DV15: 36-38 | DX15: 0.01 | DZ15: Miltank | EA15: 33-35 | EC15: 0.01 | EE15: Lampent | EF15: 45-47 | EH15: 0.01 | EJ15: Lampent | EK15: 45-47 | EM15: 0.01 | EO15: Lampent | EP15: 45-47 | ER15: 0.01 | ET15: Rotom | EU15: 45-47 | EW15: 0.01 | EY15: Escavalier | EZ15: 36-38 | FB15: 0.01 | FD15: Dracozolt | FE15: 46-48 | FG15: 0.01 | FI15: Arctovish | FJ15: 49-51 | FL15: 0.01 | FN15: Arctovish | FO15: 50-52 | FQ15: 0.01 | FS15: Charmander | FT15: 48-50 | FV15: 0.01 | FX15: Golisopod | FY15: 48-50 | GA15: 0.01 | GC15: Ditto | GD15: 49-51 | GF15: 0.01 | GH15: Staraptor | GI15: 33-35 | GK15: 0.01 | GM15: Jynx | GN15: 62-64 | GP15: 0.01 | GR15: Delibird | GS15: 62-64 | GU15: 0.01 | GW15: Delibird | GX15: 62-64 | GZ15: 0.01 | HB15: Jynx | HC15: 62-64 | HE15: 0.01 | HG15: Jynx | HH15: 62-64 | HJ15: 0.01 | HL15: Chimecho | HM15: 63-65 | HO15: 0.01 | HQ15: Chimecho | HR15: 63-65 | HT15: 0.01 | HV15: Chimecho | HW15: 63-65 | HY15: 0.01 | IA15: Chimecho | IB15: 63-65 | ID15: 0.01 | IF15: Electabuzz | IG15: 63-65 | II15: 0.01 | IK15: Type: Null | IL15: 68-70 | IN15: 0.01 | IP15: Type: Null | IQ15: 68-70 | IS15: 0.01 | IU15: Type: Null | IV15: 68-70 | IX15: 0.01 | IZ15: Unown | JA15: 75-77 | JC15: 0.01 | JE15: Unown | JF15: 75-77 | JH15: 0.01 | JJ15: Metagross | JK15: 80-82 | JM15: 0.01 | JO15: Baxcalibur | JP15: 80-82 | JR15: 0.01 | JT15: Iron Bundle | JU15: 80-82 | JY15: 0.01 | KA15: Seviper | KB15: 83-85 | KD15: 0.01 | KF15: Volcarona | KG15: 83-85 | KI15: 0.01 | KK15: Arcanine-Hisui | KL15: 83-85 | KN15: 0.01 | KP15: Meltan | KQ15: 83-85 | KS15: 0.01 | KU15: Meltan | KV15: 83-85 | KX15: 0.01 | KZ15: Scyther | LA15: 83-85 | LC15: 0.01 | LE15: Hawlucha | LF15: 83-85 | LH15: 0.01 | LJ15: Durant | LK15: 83-85 | LM15: 0.01 | LO15: Mimikyu | LP15: 83-85 | LR15: 0.01 | LT15: Spiritomb | LU15: 83-85 | LW15: 0.01 | LY15: Corviknight | LZ15: 83-85
C16: 0.01 | E16: Pansear | F16: 44231 | H16: 0.01 | J16: Snover | K16: 44625 | M16: 0.01 | O16: Panpour | P16: 44625 | R16: 0.01 | T16: Capsakid | U16: 45022 | W16: 0.01 | Y16: Pansage | Z16: 44625 | AB16: 0.01 | AD16: Joltik | AE16: 44657 | AG16: 0.01 | AI16: Nymble | AJ16: 44657 | AL16: 0.01 | AN16: Noibat | AO16: 44751 | AQ16: 0.01 | AS16: Bonsly | AT16: 44751 | AV16: 0.01 | AX16: Meowth-Alola | AY16: 44846 | BA16: 0.01 | BC16: Throh | BD16: 44909 | BF16: 0.01 | BH16: Riolu | BI16: 44909 | BK16: 0.01 | BM16: Onix | BN16: 44909 | BP16: 0.01 | BR16: Rookidee | BS16: 13-15 | BU16: 0.01 | BW16: Klawf | BX16: 14-16 | BZ16: 0.01 | CB16: Zangoose | CC16: 16-18 | CE16: 0.01 | CG16: Drifloon | CH16: 18-20 | CJ16: 0.01 | CL16: Togepi | CM16: 16-18 | CO16: 0.01 | CQ16: Sigilyph | CR16: 23-25 | CT16: 0.01 | CV16: Hippopotas | CW16: 23-25 | CY16: 0.01 | DA16: Skorupi | DB16: 25-27 | DD16: 0.01 | DF16: Sneasel-Hisui | DG16: 27-29 | DI16: 0.01 | DK16: Durant | DL16: 29-31 | DN16: 0.01 | DP16: Glimmet | DQ16: 30-32 | DS16: 0.01 | DU16: Porygon | DV16: 36-38 | DX16: 0.01 | DZ16: Miltank | EA16: 33-35 | EC16: 0.01 | EE16: Lampent | EF16: 45-47 | EH16: 0.01 | EJ16: Lampent | EK16: 45-47 | EM16: 0.01 | EO16: Lampent | EP16: 45-47 | ER16: 0.01 | ET16: Rotom | EU16: 45-47 | EW16: 0.01 | EY16: Cufant | EZ16: 36-38 | FB16: 0.01 | FD16: Dracozolt | FE16: 46-48 | FG16: 0.01 | FI16: Dracovish | FJ16: 49-51 | FL16: 0.01 | FN16: Arctozolt | FO16: 50-52 | FQ16: 0.01 | FS16: Charmander | FT16: 48-50 | FV16: 0.01 | FX16: Golisopod | FY16: 48-50 | GA16: 0.01 | GC16: Ditto | GD16: 49-51 | GF16: 0.01 | GH16: Staraptor | GI16: 33-35 | GK16: 0.01 | GM16: Jynx | GN16: 62-64 | GP16: 0.01 | GR16: Delibird | GS16: 62-64 | GU16: 0.01 | GW16: Delibird | GX16: 62-64 | GZ16: 0.01 | HB16: Jynx | HC16: 62-64 | HE16: 0.01 | HG16: Jynx | HH16: 62-64 | HJ16: 0.01 | HL16: Chimecho | HM16: 63-65 | HO16: 0.01 | HQ16: Chimecho | HR16: 63-65 | HT16: 0.01 | HV16: Chimecho | HW16: 63-65 | HY16: 0.01 | IA16: Chimecho | IB16: 63-65 | ID16: 0.01 | IF16: Electabuzz | IG16: 63-65 | II16: 0.01 | IK16: Type: Null | IL16: 68-70 | IN16: 0.01 | IP16: Type: Null | IQ16: 68-70 | IS16: 0.01 | IU16: Type: Null | IV16: 68-70 | IX16: 0.01 | IZ16: Unown | JA16: 75-77 | JC16: 0.01 | JE16: Unown | JF16: 75-77 | JH16: 0.01 | JJ16: Salamence | JK16: 80-82 | JM16: 0.01 | JO16: Tyranitar | JP16: 80-82 | JR16: 0.01 | JT16: Dragonite | JU16: 80-82 | JY16: 0.01 | KA16: Seviper | KB16: 83-85 | KD16: 0.01 | KF16: Volcarona | KG16: 83-85 | KI16: 0.01 | KK16: Arcanine-Hisui | KL16: 83-85 | KN16: 0.01 | KP16: Meltan | KQ16: 83-85 | KS16: 0.01 | KU16: Meltan | KV16: 83-85 | KX16: 0.01 | KZ16: Scyther | LA16: 83-85 | LC16: 0.01 | LE16: Hawlucha | LF16: 83-85 | LH16: 0.01 | LJ16: Durant | LK16: 83-85 | LM16: 0.01 | LO16: Mimikyu | LP16: 83-85 | LR16: 0.01 | LT16: Spiritomb | LU16: 83-85 | LW16: 0.01 | LY16: Corviknight | LZ16: 83-85
C18: =Source!$C9 | D18: ROUTE 1 | H18: =Source!$C9 | I18: VIRIDIAN CITY | M18: =Source!$C9 | N18: ROUTE 22 | R18: =Source!$C9 | S18: ROUTE 21A | W18: =Source!$C9 | X18: ROUTE 2 | AB18: =Source!$C9 | AC18: VIRIDIAN FOREST | AG18: =Source!$C9 | AH18: FOREST EXPANSION | AL18: =Source!$C9 | AM18: DIGLETT CAVE | AQ18: =Source!$C9 | AR18: PEWTER CITY | AV18: =Source!$C9 | AW18: ROUTE 3 | BA18: =Source!$C9 | BB18: MT MOON 1F | BF18: =Source!$C9 | BG18: MT MOON B1F | BK18: =Source!$C9 | BL18: MT MOON B2F | BP18: =Source!$C9 | BQ18: ROUTE 4 | BU18: =Source!$C9 | BV18: ROUTE 24 | BZ18: =Source!$C9 | CA18: ROUTE 25 | CE18: =Source!$C9 | CF18: ROUTE 5 | CJ18: =Source!$C9 | CK18: ROUTE 6 | CO18: =Source!$C9 | CP18: ROUTE 11 | CT18: =Source!$C9 | CU18: DIGLETT CAVE B1F | CY18: =Source!$C9 | CZ18: ROUTE 9 | DD18: =Source!$C9 | DE18: ROUTE 10 | DI18: =Source!$C9 | DJ18: ROCK TUNNEL 1F | DN18: =Source!$C9 | DO18: ROCK TUNNEL B1F | DS18: =Source!$C9 | DT18: ROUTE 7 | DX18: =Source!$C9 | DY18: ROUTE 8 | EC18: =Source!$C9 | ED18: PKMN TOWER 3&5F | EH18: =Source!$C9 | EI18: PKMN TOWER 4F | EM18: =Source!$C9 | EN18: PKMN TOWER 6F | ER18: =Source!$C9 | ES18: PKMN TOWER 7F | EW18: =Source!$C9 | EX18: ROUTE 16 | FB18: =Source!$C9 | FC18: ROUTE 17 | FG18: =Source!$C9 | FH18: ROUTE 18 | FL18: =Source!$C9 | FM18: ROUTE 12 | FQ18: =Source!$C9 | FR18: ROUTE 13 | FV18: =Source!$C9 | FW18: ROUTE 14 | GA18: =Source!$C9 | GB18: ROUTE 15 | GF18: =Source!$C9 | GG18: ROUTE 23 | GK18: =Source!$C9 | GL18: SEAFOAM 1F | GP18: =Source!$C9 | GQ18: SEAFOAM B1F | GU18: =Source!$C9 | GV18: SEAFOAM B2F | GZ18: =Source!$C9 | HA18: SEAFOAM B3F | HE18: =Source!$C9 | HF18: SEAFOAM B4F | HJ18: =Source!$C9 | HK18: MANSION 1F | HO18: =Source!$C9 | HP18: MANSION 2F | HT18: =Source!$C9 | HU18: MANSION 3F | HY18: =Source!$C9 | HZ18: MANSION B1F | ID18: =Source!$C9 | IE18: POWER PLANT | II18: =Source!$C9 | IJ18: CERULEAN CAVE 1F | IN18: =Source!$C9 | IO18: CERULEAN CAVE 2F | IS18: =Source!$C9 | IT18: CERULEAN CAVE B1F | IX18: =Source!$C9 | IY18: MANSION 4F | JC18: =Source!$C9 | JD18: GOUGING'S ROOM | JH18: =Source!$C9 | JI18: VICTORY ROAD 1F | JM18: =Source!$C9 | JN18: VICTORY ROAD 2F | JR18: =Source!$C9 | JS18: VICTORY ROAD 3F | JY18: =Source!$C9 | JZ18: KINDLE ROAD | KD18: =Source!$C9 | KE18: MT. EMBER EXTERIOR | KI18: =Source!$C9 | KJ18: MT. EMBER 1F | KN18: =Source!$C9 | KO18: TREASURE BEACH | KS18: =Source!$C9 | KT18: ROCK TUNNEL (SECRET) | KX18: =Source!$C9 | KY18: CAPE BRINK | LC18: =Source!$C9 | LD18: BOND BRIDGE | LH18: =Source!$C9 | LI18: BERRY FOREST | LM18: =Source!$C9 | LN18: PKMN TOWER 8F | LR18: =Source!$C9 | LS18: PKMN TOWER 9F | LW18: =Source!$C9 | LX18: THREE ISLAND
C19: Rarity | D19: Pokémon | F19: Level | H19: Rarity | I19: Pokémon | K19: Level | M19: Rarity | N19: Pokémon | P19: Level | R19: Rarity | S19: Pokémon | U19: Level | W19: Rarity | X19: Pokémon | Z19: Level | AB19: Rarity | AC19: Pokémon | AE19: Level | AG19: Rarity | AH19: Pokémon | AJ19: Level | AL19: Rarity | AM19: Pokémon | AO19: Level | AQ19: Rarity | AR19: Pokémon | AT19: Level | AV19: Rarity | AW19: Pokémon | AY19: Level | BA19: Rarity | BB19: Pokémon | BD19: Level | BF19: Rarity | BG19: Pokémon | BI19: Level | BK19: Rarity | BL19: Pokémon | BN19: Level | BP19: Rarity | BQ19: Pokémon | BS19: Level | BU19: Rarity | BV19: Pokémon | BX19: Level | BZ19: Rarity | CA19: Pokémon | CC19: Level | CE19: Rarity | CF19: Pokémon | CH19: Level | CJ19: Rarity | CK19: Pokémon | CM19: Level | CO19: Rarity | CP19: Pokémon | CR19: Level | CT19: Rarity | CU19: Pokémon | CW19: Level | CY19: Rarity | CZ19: Pokémon | DB19: Level | DD19: Rarity | DE19: Pokémon | DG19: Level | DI19: Rarity | DJ19: Pokémon | DL19: Level | DN19: Rarity | DO19: Pokémon | DQ19: Level | DS19: Rarity | DT19: Pokémon | DV19: Level | DX19: Rarity | DY19: Pokémon | EA19: Level | EC19: Rarity | ED19: Pokémon | EF19: Level | EH19: Rarity | EI19: Pokémon | EK19: Level | EM19: Rarity | EN19: Pokémon | EP19: Level | ER19: Rarity | ES19: Pokémon | EU19: Level | EW19: Rarity | EX19: Pokémon | EZ19: Level | FB19: Rarity | FC19: Pokémon | FE19: Level | FG19: Rarity | FH19: Pokémon | FJ19: Level | FL19: Rarity | FM19: Pokémon | FO19: Level | FQ19: Rarity | FR19: Pokémon | FT19: Level | FV19: Rarity | FW19: Pokémon | FY19: Level | GA19: Rarity | GB19: Pokémon | GD19: Level | GF19: Rarity | GG19: Pokémon | GI19: Level | GK19: Rarity | GL19: Pokémon | GN19: Level | GP19: Rarity | GQ19: Pokémon | GS19: Level | GU19: Rarity | GV19: Pokémon | GX19: Level | GZ19: Rarity | HA19: Pokémon | HC19: Level | HE19: Rarity | HF19: Pokémon | HH19: Level | HJ19: Rarity | HK19: Pokémon | HM19: Level | HO19: Rarity | HP19: Pokémon | HR19: Level | HT19: Rarity | HU19: Pokémon | HW19: Level | HY19: Rarity | HZ19: Pokémon | IB19: Level | ID19: Rarity | IE19: Pokémon | IG19: Level | II19: Rarity | IJ19: Pokémon | IL19: Level | IN19: Rarity | IO19: Pokémon | IQ19: Level | IS19: Rarity | IT19: Pokémon | IV19: Level | IX19: Rarity | IY19: Pokémon | JA19: Level | JC19: Rarity | JD19: Pokémon | JF19: Level | JH19: Rarity | JI19: Pokémon | JK19: Level | JM19: Rarity | JN19: Pokémon | JP19: Level | JR19: Rarity | JS19: Pokémon | JU19: Level | JY19: Rarity | JZ19: Pokémon | KB19: Level | KD19: Rarity | KE19: Pokémon | KG19: Level | KI19: Rarity | KJ19: Pokémon | KL19: Level | KN19: Rarity | KO19: Pokémon | KQ19: Level | KS19: Rarity | KT19: Pokémon | KV19: Level | KX19: Rarity | KY19: Pokémon | LA19: Level | LC19: Rarity | LD19: Pokémon | LF19: Level | LH19: Rarity | LI19: Pokémon | LK19: Level | LM19: Rarity | LN19: Pokémon | LP19: Level | LR19: Rarity | LS19: Pokémon | LU19: Level | LW19: Rarity | LX19: Pokémon | LZ19: Level
C20: 0.2 | D20: {=IFERROR(VLOOKUP(E20:E31,Dex!$B$3:$N33,2,FALSE),"")} | E20: Poochyena | F20: 44231 | H20: 0.2 | I20: {=IFERROR(VLOOKUP(J20:J31,Dex!$B$3:$N33,2,FALSE),"")} | J20: Pawmi | K20: 44625 | M20: 0.2 | N20: {=IFERROR(VLOOKUP(O20:O31,Dex!$B$3:$N33,2,FALSE),"")} | O20: Starly | P20: 44625 | R20: 0.2 | S20: {=IFERROR(VLOOKUP(T20:T31,Dex!$B$3:$N33,2,FALSE),"")} | T20: Wooper-Paldea | U20: 45022 | W20: 0.2 | X20: {=IFERROR(VLOOKUP(Y20:Y31,Dex!$B$3:$N33,2,FALSE),"")} | Y20: Poochyena | Z20: 44625 | AB20: 0.2 | AC20: {=IFERROR(VLOOKUP(AD20:AD31,Dex!$B$3:$N33,2,FALSE),"")} | AD20: Spinarak | AE20: 44657 | AG20: 0.2 | AH20: {=IFERROR(VLOOKUP(AI20:AI31,Dex!$B$3:$N33,2,FALSE),"")} | AI20: Tarountula | AJ20: 44657 | AL20: 0.2 | AM20: {=IFERROR(VLOOKUP(AN20:AN31,Dex!$B$3:$N33,2,FALSE),"")} | AN20: Diglett-Alola | AO20: 44751 | AQ20: 0.2 | AR20: {=IFERROR(VLOOKUP(AS20:AS21,Dex!$B$3:$N33,2,FALSE),"")} | AS20: Grimer-Alola | AT20: 44751 | AV20: 0.2 | AW20: {=IFERROR(VLOOKUP(AX20:AX31,Dex!$B$3:$N33,2,FALSE),"")} | AX20: Fletchling | AY20: 44846 | BA20: 0.2 | BB20: {=IFERROR(VLOOKUP(BC20:BC31,Dex!$B$3:$N33,2,FALSE),"")} | BC20: Geodude-Alola | BD20: 44909 | BF20: 0.2 | BG20: {=IFERROR(VLOOKUP(BH20:BH31,Dex!$B$3:$N33,2,FALSE),"")} | BH20: Paras | BI20: 44909 | BK20: 0.2 | BL20: {=IFERROR(VLOOKUP(BM20:BM31,Dex!$B$3:$N33,2,FALSE),"")} | BM20: Mawile | BN20: 44909 | BP20: 0.2 | BQ20: {=IFERROR(VLOOKUP(BR20:BR31,Dex!$B$3:$N33,2,FALSE),"")} | BR20: Pidove | BS20: 13-15 | BU20: 0.2 | BV20: {=IFERROR(VLOOKUP(BW20:BW31,Dex!$B$3:$N33,2,FALSE),"")} | BW20: Snubbull | BX20: 14-16 | BZ20: 0.2 | CA20: {=IFERROR(VLOOKUP(CB20:CB31,Dex!$B$3:$N33,2,FALSE),"")} | CB20: Swablu | CC20: 16-18 | CE20: 0.2 | CF20: {=IFERROR(VLOOKUP(CG20:CG31,Dex!$B$3:$N33,2,FALSE),"")} | CG20: Meowth-Galar | CH20: 18-20 | CJ20: 0.2 | CK20: {=IFERROR(VLOOKUP(CL20:CL31,Dex!$B$3:$N33,2,FALSE),"")} | CL20: Bounsweet | CM20: 16-18 | CO20: 0.2 | CP20: {=IFERROR(VLOOKUP(CQ20:CQ31,Dex!$B$3:$N33,2,FALSE),"")} | CQ20: Pancham | CR20: 23-25 | CT20: 0.2 | CU20: {=IFERROR(VLOOKUP(CV20:CV31,Dex!$B$3:$N33,2,FALSE),"")} | CV20: Diglett-Alola | CW20: 23-25 | CY20: 0.2 | CZ20: {=IFERROR(VLOOKUP(DA20:DA31,Dex!$B$3:$N33,2,FALSE),"")} | DA20: Shelmet | DB20: 25-27 | DD20: 0.2 | DE20: {=IFERROR(VLOOKUP(DF20:DF31,Dex!$B$3:$N33,2,FALSE),"")} | DF20: Voltorb-Hisui | DG20: 27-29 | DI20: 0.2 | DJ20: {=IFERROR(VLOOKUP(DK20:DK31,Dex!$B$3:$N33,2,FALSE),"")} | DK20: Graveler-Alola | DL20: 29-31 | DN20: 0.2 | DO20: {=IFERROR(VLOOKUP(DP20:DP31,Dex!$B$3:$N33,2,FALSE),"")} | DP20: Bergmite | DQ20: 30-32 | DS20: 0.2 | DT20: {=IFERROR(VLOOKUP(DU20:DU31,Dex!$B$3:$N33,2,FALSE),"")} | DU20: Deerling-Winter | DV20: 36-38 | DX20: 0.2 | DY20: {=IFERROR(VLOOKUP(DZ20:DZ31,Dex!$B$3:$N33,2,FALSE),"")} | DZ20: Foongus | EA20: 33-35 | EC20: 0.2 | ED20: {=IFERROR(VLOOKUP(EE20:EE31,Dex!$B$3:$N33,2,FALSE),"")} | EE20: Haunter | EF20: 45-47 | EH20: 0.2 | EI20: {=IFERROR(VLOOKUP(EJ20:EJ31,Dex!$B$3:$N33,2,FALSE),"")} | EJ20: Haunter | EK20: 45-47 | EM20: 0.2 | EN20: {=IFERROR(VLOOKUP(EO20:EO31,Dex!$B$3:$N33,2,FALSE),"")} | EO20: Haunter | EP20: 45-47 | ER20: 0.2 | ES20: {=IFERROR(VLOOKUP(ET20:ET31,Dex!$B$3:$N33,2,FALSE),"")} | ET20: Haunter | EU20: 45-47 | EW20: 0.2 | EX20: {=IFERROR(VLOOKUP(EY20:EY31,Dex!$B$3:$N33,2,FALSE),"")} | EY20: Scyther | EZ20: 36-38 | FB20: 0.2 | FC20: {=IFERROR(VLOOKUP(FD20:FD31,Dex!$B$3:$N33,2,FALSE),"")} | FD20: Weezing-Galar | FE20: 46-48 | FG20: 0.2 | FH20: {=IFERROR(VLOOKUP(FI20:FI31,Dex!$B$3:$N33,2,FALSE),"")} | FI20: Xatu | FJ20: 49-51 | FL20: 0.2 | FM20: {=IFERROR(VLOOKUP(FN20:FN31,Dex!$B$3:$N33,2,FALSE),"")} | FN20: Sneasel | FO20: 50-52 | FQ20: 0.2 | FR20: {=IFERROR(VLOOKUP(FS20:FS31,Dex!$B$3:$N33,2,FALSE),"")} | FS20: Talonflame | FT20: 48-50 | FV20: 0.2 | FW20: {=IFERROR(VLOOKUP(FX20:FX31,Dex!$B$3:$N33,2,FALSE),"")} | FX20: Pelipper | FY20: 48-50 | GA20: 0.2 | GB20: {=IFERROR(VLOOKUP(GC20:GC31,Dex!$B$3:$N33,2,FALSE),"")} | GC20: Amoonguss | GD20: 49-51 | GF20: 0.2 | GG20: {=IFERROR(VLOOKUP(GH20:GH31,Dex!$B$3:$N33,2,FALSE),"")} | GH20: Primeape | GI20: 33-35 | GK20: 0.2 | GL20: {=IFERROR(VLOOKUP(GM20:GM31,Dex!$B$3:$N33,2,FALSE),"")} | GM20: Sandslash-Alola | GN20: 62-64 | GP20: 0.2 | GQ20: {=IFERROR(VLOOKUP(GR20:GR31,Dex!$B$3:$N33,2,FALSE),"")} | GR20: Sandslash-Alola | GS20: 62-64 | GU20: 0.2 | GV20: {=IFERROR(VLOOKUP(GW20:GW31,Dex!$B$3:$N33,2,FALSE),"")} | GW20: Abomasnow | GX20: 62-64 | GZ20: 0.2 | HA20: {=IFERROR(VLOOKUP(HB20:HB31,Dex!$B$3:$N33,2,FALSE),"")} | HB20: Sandslash-Alola | HC20: 62-64 | HE20: 0.2 | HF20: {=IFERROR(VLOOKUP(HG20:HG31,Dex!$B$3:$N33,2,FALSE),"")} | HG20: Piloswine | HH20: 62-64 | HJ20: 0.2 | HK20: {=IFERROR(VLOOKUP(HL20:HL31,Dex!$B$3:$N33,2,FALSE),"")} | HL20: Raticate-Alola | HM20: 63-65 | HO20: 0.2 | HP20: {=IFERROR(VLOOKUP(HQ20:HQ31,Dex!$B$3:$N33,2,FALSE),"")} | HQ20: Obstagoon | HR20: 63-65 | HT20: 0.2 | HU20: {=IFERROR(VLOOKUP(HV20:HV31,Dex!$B$3:$N33,2,FALSE),"")} | HV20: Komala | HW20: 63-65 | HY20: 0.2 | HZ20: {=IFERROR(VLOOKUP(IA20:IA31,Dex!$B$3:$N33,2,FALSE),"")} | IA20: Raticate-Alola | IB20: 63-65 | ID20: 0.2 | IE20: {=IFERROR(VLOOKUP(IF20:IF31,Dex!$B$3:$N33,2,FALSE),"")} | IF20: Magneton | IG20: 63-65 | II20: 0.2 | IJ20: {=IFERROR(VLOOKUP(IK20:IK31,Dex!$B$3:$N33,2,FALSE),"")} | IK20: Parasect | IL20: 68-70 | IN20: 0.2 | IO20: {=IFERROR(VLOOKUP(IP20:IP31,Dex!$B$3:$N33,2,FALSE),"")} | IP20: Brute Bonnet | IQ20: 68-70 | IS20: 0.2 | IT20: {=IFERROR(VLOOKUP(IU20:IU31,Dex!$B$3:$N33,2,FALSE),"")} | IU20: Iron Treads | IV20: 68-70 | IX20: 0.2 | IY20: {=IFERROR(VLOOKUP(IZ20:IZ31,Dex!$B$3:$N33,2,FALSE),"")} | IZ20: Unown | JA20: 75-77 | JC20: 0.2 | JD20: {=IFERROR(VLOOKUP(JE20:JE31,Dex!$B$3:$N33,2,FALSE),"")} | JE20: Unown | JF20: 75-77 | JH20: 0.2 | JI20: {=IFERROR(VLOOKUP(JJ20:JJ31,Dex!$B$3:$N33,2,FALSE),"")} | JJ20: Flutter Mane | JK20: 80-82 | JM20: 0.2 | JN20: {=IFERROR(VLOOKUP(JO20:JO31,Dex!$B$3:$N33,2,FALSE),"")} | JO20: Baxcalibur | JP20: 80-82 | JR20: 0.2 | JS20: {=IFERROR(VLOOKUP(JT20:JT31,Dex!$B$3:$N33,2,FALSE),"")} | JT20: Dragonite | JU20: 80-82 | JY20: 0.2 | JZ20: {=IFERROR(VLOOKUP(KA20:KA31,Dex!$B$3:$N33,2,FALSE),"")} | KA20: Absol | KB20: 83-85 | KD20: 0.2 | KE20: {=IFERROR(VLOOKUP(KF20:KF31,Dex!$B$3:$N33,2,FALSE),"")} | KF20: Doduo-Sevii | KG20: 60-65 | KI20: 0.2 | KJ20: {=IFERROR(VLOOKUP(KK20:KK31,Dex!$B$3:$N33,2,FALSE),"")} | KK20: Torkoal | KL20: 85-85 | KN20: 0.2 | KO20: {=IFERROR(VLOOKUP(KP20:KP31,Dex!$B$3:$N33,2,FALSE),"")} | KP20: Sirfetch'd | KQ20: 85-85 | KS20: 0.2 | KT20: {=IFERROR(VLOOKUP(KU20:KU31,Dex!$B$3:$N33,2,FALSE),"")} | KU20: Ursaluna | KV20: 85-85 | KX20: 0.2 | KY20: {=IFERROR(VLOOKUP(KZ20:KZ31,Dex!$B$3:$N33,2,FALSE),"")} | KZ20: Electrode-Hisui | LA20: 85-85 | LC20: 0.2 | LD20: {=IFERROR(VLOOKUP(LE20:LE31,Dex!$B$3:$N33,2,FALSE),"")} | LE20: Decidueye-Hisui | LF20: 85-85 | LH20: 0.2 | LI20: {=IFERROR(VLOOKUP(LJ20:LJ31,Dex!$B$3:$N33,2,FALSE),"")} | LJ20: Carnivine-Sevii | LK20: 85-85 | LM20: 0.2 | LN20: {=IFERROR(VLOOKUP(LO20:LO31,Dex!$B$3:$N33,2,FALSE),"")} | LO20: Teddiursa-Sevii | LP20: 85-85 | LR20: 0.2 | LS20: {=IFERROR(VLOOKUP(LT20:LT31,Dex!$B$3:$N33,2,FALSE),"")} | LT20: Wishiwashi-Sevii | LU20: 85-85 | LW20: 0.2 | LX20: {=IFERROR(VLOOKUP(LY20:LY31,Dex!$B$3:$N33,2,FALSE),"")} | LY20: Dunsparce | LZ20: 85-85
C21: 0.2 | E21: Zigzagoon-Galar | F21: 44231 | H21: 0.2 | J21: Mareep | K21: 44625 | M21: 0.2 | O21: Sandshrew-Alola | P21: 44625 | R21: 0.2 | T21: Lechonk | U21: 45022 | W21: 0.2 | Y21: Sentret | Z21: 44625 | AB21: 0.2 | AD21: Wurmple | AE21: 44657 | AG21: 0.2 | AI21: Blipbug | AJ21: 44657 | AL21: 0.2 | AN21: Nacli | AO21: 44751 | AQ21: 0.2 | AS21: Starly | AT21: 44751 | AV21: 0.2 | AX21: Ekans | AY21: 44846 | BA21: 0.2 | BC21: Zubat | BD21: 44909 | BF21: 0.2 | BH21: Nacli | BI21: 44909 | BK21: 0.2 | BM21: Zubat | BN21: 44909 | BP21: 0.2 | BR21: Oddish | BS21: 13-15 | BU21: 0.2 | BW21: Cottonee | BX21: 14-16 | BZ21: 0.2 | CB21: Taillow | CC21: 16-18 | CE21: 0.2 | CG21: Hatenna | CH21: 18-20 | CJ21: 0.2 | CL21: Gossifleur | CM21: 16-18 | CO21: 0.2 | CQ21: Ducklett | CR21: 23-25 | CT21: 0.2 | CV21: Diglett-Alola | CW21: 23-25 | CY21: 0.2 | DA21: Exeggcute | DB21: 25-27 | DD21: 0.2 | DF21: Electrike | DG21: 27-29 | DI21: 0.2 | DK21: Aron | DL21: 29-31 | DN21: 0.2 | DP21: Rhyhorn | DQ21: 30-32 | DS21: 0.2 | DU21: Inkay | DV21: 36-38 | DX21: 0.2 | DZ21: Minccino | EA21: 33-35 | EC21: 0.2 | EE21: Runerigus | EF21: 45-47 | EH21: 0.2 | EJ21: Runerigus | EK21: 45-47 | EM21: 0.2 | EO21: Runerigus | EP21: 45-47 | ER21: 0.2 | ET21: Runerigus | EU21: 45-47 | EW21: 0.2 | EY21: Forretress | EZ21: 36-38 | FB21: 0.2 | FD21: Cyclizar | FE21: 46-48 | FG21: 0.2 | FI21: Vikavolt | FJ21: 49-51 | FL21: 0.2 | FN21: Dewgong | FO21: 50-52 | FQ21: 0.2 | FS21: Pyroar | FT21: 48-50 | FV21: 0.2 | FX21: Swadloon | FY21: 48-50 | GA21: 0.2 | GC21: Ambipom | GD21: 49-51 | GF21: 0.2 | GH21: Fearow | GI21: 33-35 | GK21: 0.2 | GM21: Snorunt | GN21: 62-64 | GP21: 0.2 | GR21: Darmanitan-Galar | GS21: 62-64 | GU21: 0.2 | GW21: Snorunt | GX21: 62-64 | GZ21: 0.2 | HB21: Darmanitan-Galar | HC21: 62-64 | HE21: 0.2 | HG21: Abomasnow | HH21: 62-64 | HJ21: 0.2 | HL21: Audino | HM21: 63-65 | HO21: 0.2 | HQ21: Garbodor | HR21: 63-65 | HT21: 0.2 | HV21: Seviper | HW21: 63-65 | HY21: 0.2 | IA21: Garbodor | IB21: 63-65 | ID21: 0.2 | IF21: Electrode | IG21: 63-65 | II21: 0.2 | IK21: Golbat | IL21: 68-70 | IN21: 0.2 | IP21: Iron Treads | IQ21: 68-70 | IS21: 0.2 | IU21: Noivern | IV21: 68-70 | IX21: 0.2 | IZ21: Unown | JA21: 75-77 | JC21: 0.2 | JE21: Unown | JF21: 75-77 | JH21: 0.2 | JJ21: Metagross | JK21: 80-82 | JM21: 0.2 | JO21: Garchomp | JP21: 80-82 | JR21: 0.2 | JT21: Roaring Moon | JU21: 80-82 | JY21: 0.2 | KA21: Smeargle | KB21: 83-85 | KD21: 0.2 | KF21: Coalossal | KG21: 83-85 | KI21: 0.2 | KK21: Magcargo | KL21: 84-85 | KN21: 0.2 | KP21: Sirfetch'd | KQ21: 84-85 | KS21: 0.2 | KU21: Noibat-Sevii | KV21: 84-85 | KX21: 0.2 | KZ21: Blitzle-Sevii | LA21: 84-85 | LC21: 0.2 | LE21: Sneasel-Hisui | LF21: 84-85 | LH21: 0.2 | LJ21: Nymble-Sevii | LK21: 84-85 | LM21: 0.2 | LO21: Zoroark-Hisui | LP21: 84-85 | LR21: 0.2 | LT21: Typhlosion-Hisui | LU21: 84-85 | LW21: 0.2 | LY21: Clauncher-Sevii | LZ21: 84-85
